Workbook

Sheet Hoja1
A1: Country | B1: Year | C1: CO2 Emissions (Mt CO2e) | D1: Age dependency ratio(%) | E1: Trade (% of GDP) | F1: GDP growth (%) | G1: Coeficiente inverso de variacion | H1: HIRSCHMAN-HERFINDAHL INDEX (HHI) | I1: Adjusted net saving (%) | J1: Goverment Debt (%) | K1: Air pollution (%) | L1: Intensidad de CO2 (kg CO2 per) | M1: Renewable energy consumption (%) | N1: Energy intensity (MJ) | O1: Renewable freshwater (cubic meters) | P1: Natural resources rents (%) | Q1: Water productivity ($ GDP por metro cubico) | R1: Acces electricity (%) | S1: Using drinking water (%) | T1: Employment (%) | U1: indice de Gini | V1: Mortaly rate (%) | W1: Life expentacy (years) | X1: Poverty gap (%) | Y1: Primary completion (%) | Z1: Sanitation services (%) | AA1: School enrollment, gender parity index | AB1: LABOR FORCE PARTICIPATION (% POINTS) | AC1: Years scholling | AE1: Indice de crecimiento verde | AF1: Students abilities | AG1: Educational attainment (%) | AH1: Dwellings without basic facilities (%) | AI1: Housing expenditure (%) | AJ1: Adjusted net national ($) | AK1: Household net wealth (%) | AL1: Unemployed long term (%) | AM1: Personal earning ($) | AN1: Quality of support network (%) | AO1: Stakeholder engagement | AP1: Life satisfaction | AQ1: Homicide rate (por cada 100,000) | AR1: Time to leisure ande personal care | AT1: Maximo | AU1: =MAX(D2:D719) -> 48.333183 | AV1: =MAX(E2:E719) -> 394.22069 | AW1: =MAX(F2:F719) -> 7.4532705 | AX1: =MAX(G2:G719) -> 11.678952 | AY1: =MAX(H2:H719) -> 5681.2269 | AZ1: =MAX(I2:I719) -> 29.320131 | BA1: =MAX(J2:J719) -> 249.41135 | BC1: =MAX(K2:K719) -> 100 | BD1: =MAX(L2:L719) -> 1.4048614 | BE1: =MAX(M2:M719) -> 82.9 | BF1: =MAX(N2:N719) -> 15.65 | BG1: =MAX(O2:O719) -> 535578.14 | BH1: =MAX(P2:P719) -> 19.104979 | BI1: =MAX(Q2:Q719) -> 1478.6535 | BK1: =MAX(R2:R719) -> 100 | BL1: =MAX(S2:S719) -> 100 | BM1: =MAX(T2:T719) -> 81.311 | BN1: =MAX(U2:U719) -> 55.3 | BO1: =MAX(V2:V719) -> 18.4 | BP1: =MAX(W2:W719) -> 84.56 | BQ1: =MAX(X2:X719) -> 9.7 | BR1: =MAX(Y2:Y719) -> 100 | ... BV1: =MAX(AC2:AC719) -> 14.256
A2: Australia | B2: 2008 | C2: 404.2851 | D2: 28.606482 | E2: 42.846776 | F2: 0.015311501 | G2: 2.8782704 | H2: 1031.3084 | I2: 6.3246052 | J2: 18.180547 | K2: 33.49242 | L2: 0.35671708 | M2: 6.8 | N2: 5.38 | O2: 23153.814 | P2: 8.5264194 | Q2: 74.545052 | R2: 100 | S2: 99.842555 | T2: 62.719 | U2: 35.4 | V2: 4.4 | W2: 81.395122 | X2: 0.4 | Y2: 99.25 | Z2: 99.994743 | AB2: 14.097 | AC2: 11.938 | AE2: =AVERAGE(BJ4,BX4,BB4) -> 4.4866101 | AG2: 70.089996 | AH2: 1.1 | AI2: 21.783196 | AJ2: 44512.596 | AK2: 332.0227 | AL2: 18.715849 | AM2: 54149 | AN2: 94.188943 | AO2: 2.79 | AQ2: 1.2283582 | AR2: 20.83 | AT2: Minimo | AU2: =MIN(D2:D719) -> 15.518704 | AV2: =MIN(E2:E719) -> 22.105976 | AW2: =MIN(F2:F719) -> -1.4776721 | AX2: =MIN(G2:G719) -> -1.862159 | AY2: =MIN(H2:H719) -> 0 | AZ2: =MIN(I2:I719) -> -11.351246 | BA2: =MIN(J2:J719) -> 4.92 | BC2: =MIN(K2:K719) -> 0 | BD2: =MIN(L2:L719) -> 0.042993266 | BE2: =MIN(M2:M719) -> 1.1 | BF2: =MIN(N2:N719) -> 0.97 | BG2: =MIN(O2:O719) -> 80.030732 | BH2: =MIN(P2:P719) -> 0 | BI2: =MIN(Q2:Q719) -> 5.3462772 | BK2: =MIN(R2:R719) -> 96.1 | BL2: =MIN(S2:S719) -> 90.36157 | BM2: =MIN(T2:T719) -> 37.398 | BN2: =MIN(U2:U719) -> 0.319 | BO2: =MIN(V2:V719) -> 1.5 | BP2: =MIN(W2:W719) -> 67.949268 | BQ2: =MIN(X2:X719) -> 0 | BR2: =MIN(Y2:Y719) -> 84.57 | ... BV2: =MIN(AC2:AC719) -> 6.396
A3: Australia | B3: =B2+1 -> 2009 | C3: 410.2594 | D3: 28.422457 | E3: 45.740863 | F3: 0.015311501 | G3: 1.5095894 | H3: 1130.0822 | I3: 9.5391911 | J3: 23.868655 | K3: =(K2+K5)/2 -> 33.231697 | L3: 0.35526486 | M3: 7.1 | N3: 5.28 | O3: 22681.536 | P3: 4.9677734 | Q3: 82.326848 | R3: 100 | S3: 99.863675 | T3: 61.806 | V3: 4.2 | W3: 81.543902 | X3: 0.4 | Y3: 99.27 | Z3: 99.995241 | AB3: 13.577 | AC3: 11.987 | AE3: =AVERAGE(BJ5,BX5,BB5) -> 4.5242927 | AF3: 527 | AG3: 70.860001 | AH3: 1.1 | AI3: 22.170778 | AJ3: 44512.596 | AK3: 361.7391 | AL3: 20.578651 | AM3: 53644 | AO3: 2.79 | AQ3: 1.2141698 | AR3: 20.83 | BB3: Promedio | BG3: 2 | BJ3: Promedio | BX3: Promedio
A4: Australia | B4: =B3+1 -> 2010 | C4: 415.2731 | D4: 28.291286 | E4: 40.521589 | F4: 0.0064204349 | G4: 1.2693783 | H4: 1324.7787 | I4: 7.4710948 | J4: 28.663398 | K4: =(K3+K5)/2 -> 33.101335 | L4: 0.35179667 | M4: 8.2 | N4: 5.17 | O4: 22331.408 | P4: 8.0666003 | Q4: 89.596585 | R4: 100 | S4: 99.883144 | T4: 61.998 | U4: 34.7 | V4: 4 | W4: 81.695122 | X4: 0.4 | Y4: 99.58 | Z4: 99.995739 | AB4: 13.766 | AC4: 12.034 | AE4: =AVERAGE(BJ6,BX6,BB6) -> 4.4535836 | AG4: 72.800003 | AH4: 1.1 | AI4: 22.49657 | AJ4: 44512.596 | AK4: 346.5415 | AL4: 19.183172 | AM4: 55536 | AN4: 95.353709 | AO4: 2.79 | AQ4: 1.0490859 | AR4: 20.83 | AT4: Economic Growth | AU4: =((-5*(D2-AU$2))/(AU$1-$AU$2))+6 -> 4.0057922 | AV4: =((5*(E2-AV$2))/(AV$1-AV$2))+1 -> 1.2786883 | AW4: =((5*(F2-AW$2))/(AW$1-AW$2))+1 -> 1.8358488 | AX4: =((5*(G2-AX$2))/(AX$1-AX$2))+1 -> 2.7503842 | AY4: =((-5*(H2-AY$2))/(AY$1-AY$2))+6 -> 5.0923542 | AZ4: =((5*(I2-AZ$2))/(AZ$1-AZ$2))+1 -> 3.1730087 | BA4: =((-5*(J2-BA$2))/(BA$1-BA$2))+6 -> 5.7288136 | BB4: =AVERAGE(AU4:BA4) -> 3.40927 | BC4: =((-5*(K2-BC$2))/(BC$1-BC$2))+6 -> 4.325379 | BD4: =((-5*(L2-BD$2))/(BD$1-BD$2))+6 -> 4.8481858 | BE4: =((5*(M2-BE$2))/(BE$1-BE$2))+1 -> 1.3484108 | BF4: =((5*(N2-BF$2))/(BF$1-BF$2))+1 -> 2.5020436 | BG4: =((5*(O2-BG$2))/(BG$1-BG$2))+1 -> 1.2154422 | BH4: =((5*(P2-BH$2))/(BH$1-BH$2))+1 -> 3.2314653 | BI4: =((5*(Q2-BI$2))/(BI$1-BI$2))+1 -> 1.2348416 | BJ4: =AVERAGE(BC4:BI4) -> 2.6722526 | BK4: =((5*(R2-BK$2))/(BK$1-BK$2))+1 -> 6 | BL4: =((5*(S2-BL$2))/(BL$1-BL$2))+1 -> 5.9183244 | BM4: =((5*(T2-BM$2))/(BM$1-BM$2))+1 -> 3.883087 | BN4: =((-5*(U2-BN$2))/(BN$1-BN$2))+6 -> 2.8097161 | BO4: =((-5*(V2-BO$2))/(BO$1-BO$2))+6 -> 5.1420118 | BP4: =((5*(W2-BP$2))/(BP$1-BP$2))+1 -> 5.0473394 | BQ4: =((-5*(X2-BQ$2))/(BQ$1-BQ$2))+6 -> 5.7938144 | BR4: =((5*(Y2-BR$2))/(BR$1-BR$2))+1 -> 5.7569669 | BS4: =((5*(Z2-BS$2))/(BS$1-BS$2))+1 -> 5.9986754 | BT4: =((-5*(AA2-BT$2))/(BT$1-BT$2))+6 -> 32.725108 | BU4: =((-5*(AB2-BU$2))/(BU$1-BU$2))+6 -> 4.9392031 | BV4: =((5*(AC2-BV$2))/(BV$1-BV$2))+1 -> 4.5254453 | BX4: =AVERAGE(BK4:BV4) -> 7.3783077
A5: Australia | B5: =B4+1 -> 2011 | C5: 412.8096 | D5: 28.239982 | E5: 41.851132 | F5: 0.0099394651 | G5: 1.2060573 | H5: 1416.0994 | I5: 8.760958 | J5: 30.0954 | K5: 32.970973 | L5: 0.34148979 | M5: 8.3 | N5: 5.06 | O5: 22023.253 | P5: 8.7235204 | Q5: 91.475522 | R5: 100 | S5: 99.891962 | T5: 62.114 | V5: 3.8 | W5: 81.895122 | X5: 0.4 | Y5: 99.3 | Z5: 99.996238 | AB5: 13.323 | AC5: 12.116 | AE5: =AVERAGE(BJ7,BX7,BB7) -> 4.5570372 | AG5: 74.059998 | AH5: 1.1 | AI5: 22.945093 | AJ5: 44512.596 | AK5: 320.8005 | AL5: 19.320399 | AM5: 57361 | AN5: 96.66178 | AO5: 2.79 | AP5: 7.344625 | AQ5: 1.1092706 | AR5: 20.83 | AU5: =((-5*(D3-AU$2))/(AU$1-$AU$2))+6 -> 4.0338324 | AV5: =((5*(E3-AV$2))/(AV$1-AV$2))+1 -> 1.3175753 | AW5: =((5*(F3-AW$2))/(AW$1-AW$2))+1 -> 1.8358488 | AX5: =((5*(G3-AX$2))/(AX$1-AX$2))+1 -> 2.2450043 | AY5: =((-5*(H3-AY$2))/(AY$1-AY$2))+6 -> 5.0054242 | AZ5: =((5*(I3-AZ$2))/(AZ$1-AZ$2))+1 -> 3.5681989 | BA5: =((-5*(J3-BA$2))/(BA$1-BA$2))+6 -> 5.6124882 | BB5: =AVERAGE(AU5:BA5) -> 3.3740532 | BC5: =((-5*(K3-BC$2))/(BC$1-BC$2))+6 -> 4.3384152 | BD5: =((-5*(L3-BD$2))/(BD$1-BD$2))+6 -> 4.8535175 | BE5: =((5*(M3-BE$2))/(BE$1-BE$2))+1 -> 1.3667482 | BF5: =((5*(N3-BF$2))/(BF$1-BF$2))+1 -> 2.4679837 | BG5: =((5*(O3-BG$2))/(BG$1-BG$2))+1 -> 1.2110325 | BH5: =((5*(P3-BH$2))/(BH$1-BH$2))+1 -> 2.3001253 | BI5: =((5*(Q3-BI$2))/(BI$1-BI$2))+1 -> 1.2612509 | BJ5: =AVERAGE(BC5:BI5) -> 2.5427248 | BK5: =((5*(R3-BK$2))/(BK$1-BK$2))+1 -> 6 | BL5: =((5*(S3-BL$2))/(BL$1-BL$2))+1 -> 5.9292803 | BM5: =((5*(T3-BM$2))/(BM$1-BM$2))+1 -> 3.7791315 | BN5: =((-5*(U3-BN$2))/(BN$1-BN$2))+6 -> 6.02901 | BO5: =((-5*(V3-BO$2))/(BO$1-BO$2))+6 -> 5.2011834 | BP5: =((5*(W3-BP$2))/(BP$1-BP$2))+1 -> 5.0921238 | BQ5: =((-5*(X3-BQ$2))/(BQ$1-BQ$2))+6 -> 5.7938144 | BR5: =((5*(Y3-BR$2))/(BR$1-BR$2))+1 -> 5.7634478 | BS5: =((5*(Z3-BS$2))/(BS$1-BS$2))+1 -> 5.998801 | BT5: =((-5*(AA3-BT$2))/(BT$1-BT$2))+6 -> 32.725108 | BU5: =((-5*(AB3-BU$2))/(BU$1-BU$2))+6 -> 5.0046844 | BV5: =((5*(AC3-BV$2))/(BV$1-BV$2))+1 -> 4.5566158 | BX5: =AVERAGE(BK5:BV5) -> 7.6561
A6: Australia | B6: =B5+1 -> 2012 | C6: 413.3193 | D6: 28.291438 | E6: 43.164296 | F6: 0.021182553 | G6: 1.1651675 | H6: 1455.7146 | I6: 10.612918 | J6: 39.441661 | K6: 36.323423 | L6: 0.3290245 | M6: 8.3 | N6: 4.82 | O6: 21642.103 | P6: 5.2981388 | Q6: 79.165372 | R6: 100 | S6: 99.90077 | T6: 61.766 | U6: 32.6 | V6: 3.6 | W6: 82.046341 | X6: 0.4 | Y6: 99.32 | Z6: 99.996736 | AB6: 12.98 | AC6: 12.296 | AE6: =AVERAGE(BJ8,BX8,BB8) -> 4.4267682 | AF6: 527 | AG6: 76.480003 | AH6: 1.1 | AI6: 23.355176 | AJ6: 44512.596 | AK6: 355.5973 | AL6: 19.604399 | AM6: 57752 | AN6: 93.859693 | AO6: 2.79 | AQ6: 1.0691061 | AR6: 20.83 | AU6: =((-5*(D4-AU$2))/(AU$1-$AU$2))+6 -> 4.0538191 | AV6: =((5*(E4-AV$2))/(AV$1-AV$2))+1 -> 1.2474454 | AW6: =((5*(F4-AW$2))/(AW$1-AW$2))+1 -> 1.8308711 | AX6: =((5*(G4-AX$2))/(AX$1-AX$2))+1 -> 2.1563074 | AY6: =((-5*(H4-AY$2))/(AY$1-AY$2))+6 -> 4.8340734 | AZ6: =((5*(I4-AZ$2))/(AZ$1-AZ$2))+1 -> 3.3139542 | BA6: =((-5*(J4-BA$2))/(BA$1-BA$2))+6 -> 5.5144328 | BB6: =AVERAGE(AU6:BA6) -> 3.2787005 | BC6: =((-5*(K4-BC$2))/(BC$1-BC$2))+6 -> 4.3449333 | BD6: =((-5*(L4-BD$2))/(BD$1-BD$2))+6 -> 4.8662508 | BE6: =((5*(M4-BE$2))/(BE$1-BE$2))+1 -> 1.4339853 | BF6: =((5*(N4-BF$2))/(BF$1-BF$2))+1 -> 2.4305177 | BG6: =((5*(O4-BG$2))/(BG$1-BG$2))+1 -> 1.2077634 | BH6: =((5*(P4-BH$2))/(BH$1-BH$2))+1 -> 3.1111252 | BI6: =((5*(Q4-BI$2))/(BI$1-BI$2))+1 -> 1.2859224 | BJ6: =AVERAGE(BC6:BI6) -> 2.6686426 | BK6: =((5*(R4-BK$2))/(BK$1-BK$2))+1 -> 6 | BL6: =((5*(S4-BL$2))/(BL$1-BL$2))+1 -> 5.9393804 | BM6: =((5*(T4-BM$2))/(BM$1-BM$2))+1 -> 3.8009929 | BN6: =((-5*(U4-BN$2))/(BN$1-BN$2))+6 -> 2.8733744 | BO6: =((-5*(V4-BO$2))/(BO$1-BO$2))+6 -> 5.260355 | BP6: =((5*(W4-BP$2))/(BP$1-BP$2))+1 -> 5.1376424 | BQ6: =((-5*(X4-BQ$2))/(BQ$1-BQ$2))+6 -> 5.7938144 | BR6: =((5*(Y4-BR$2))/(BR$1-BR$2))+1 -> 5.8639015 | BS6: =((5*(Z4-BS$2))/(BS$1-BS$2))+1 -> 5.9989265 | BT6: =((-5*(AA4-BT$2))/(BT$1-BT$2))+6 -> 32.725108 | BU6: =((-5*(AB4-BU$2))/(BU$1-BU$2))+6 -> 4.9808845 | BV6: =((5*(AC4-BV$2))/(BV$1-BV$2))+1 -> 4.586514 | BX6: =AVERAGE(BK6:BV6) -> 7.4134078
A7: Australia | B7: =B6+1 -> 2013 | C7: 405.6523 | D7: 28.385747 | E7: 41.272879 | F7: 0.0085136469 | G7: 1.068135 | H7: 1742.8279 | I7: 9.7761713 | J7: 37.560001 | K7: 30.654543 | L7: 0.31473124 | M7: 9.2 | N7: 4.79 | O7: 21272.797 | P7: 5.3201157 | Q7: 67.311718 | R7: 100 | S7: 99.909589 | T7: 61.283 | V7: 3.5 | W7: 82.14878 | X7: 0.4 | Y7: 99.34 | Z7: 99.997234 | AB7: 12.732 | AC7: 12.019 | AE7: =AVERAGE(BJ9,BX9,BB9) -> 4.5028403 | AG7: 72.040001 | AH7: 1.1 | AI7: 23.455396 | AJ7: 44512.596 | AK7: 364.7715 | AL7: 19.816072 | AM7: 57579 | AN7: 92.723545 | AO7: 2.79 | AQ7: 1.0600654 | AR7: 20.83 | AU7: =((-5*(D5-AU$2))/(AU$1-$AU$2))+6 -> 4.0616364 | AV7: =((5*(E5-AV$2))/(AV$1-AV$2))+1 -> 1.2653101 | AW7: =((5*(F5-AW$2))/(AW$1-AW$2))+1 -> 1.8328413 | AX7: =((5*(G5-AX$2))/(AX$1-AX$2))+1 -> 2.1329263 | AY7: =((-5*(H5-AY$2))/(AY$1-AY$2))+6 -> 4.7537028 | AZ7: =((5*(I5-AZ$2))/(AZ$1-AZ$2))+1 -> 3.4725256 | BA7: =((-5*(J5-BA$2))/(BA$1-BA$2))+6 -> 5.4851474 | BB7: =AVERAGE(AU7:BA7) -> 3.2862986 | BC7: =((-5*(K5-BC$2))/(BC$1-BC$2))+6 -> 4.3514514 | BD7: =((-5*(L5-BD$2))/(BD$1-BD$2))+6 -> 4.9040917 | BE7: =((5*(M5-BE$2))/(BE$1-BE$2))+1 -> 1.4400978 | BF7: =((5*(N5-BF$2))/(BF$1-BF$2))+1 -> 2.3930518 | BG7: =((5*(O5-BG$2))/(BG$1-BG$2))+1 -> 1.2048861 | BH7: =((5*(P5-BH$2))/(BH$1-BH$2))+1 -> 3.283049 | BI7: =((5*(Q5-BI$2))/(BI$1-BI$2))+1 -> 1.292299 | BJ7: =AVERAGE(BC7:BI7) -> 2.695561 | BK7: =((5*(R5-BK$2))/(BK$1-BK$2))+1 -> 6 | BL7: =((5*(S5-BL$2))/(BL$1-BL$2))+1 -> 5.9439545 | BM7: =((5*(T5-BM$2))/(BM$1-BM$2))+1 -> 3.8142008 | BN7: =((-5*(U5-BN$2))/(BN$1-BN$2))+6 -> 6.02901 | BO7: =((-5*(V5-BO$2))/(BO$1-BO$2))+6 -> 5.3195266 | BP7: =((5*(W5-BP$2))/(BP$1-BP$2))+1 -> 5.1978445 | BQ7: =((-5*(X5-BQ$2))/(BQ$1-BQ$2))+6 -> 5.7938144 | BR7: =((5*(Y5-BR$2))/(BR$1-BR$2))+1 -> 5.7731692 | BS7: =((5*(Z5-BS$2))/(BS$1-BS$2))+1 -> 5.9990521 | BT7: =((-5*(AA5-BT$2))/(BT$1-BT$2))+6 -> 32.725108 | BU7: =((-5*(AB5-BU$2))/(BU$1-BU$2))+6 -> 5.0366695 | BV7: =((5*(AC5-BV$2))/(BV$1-BV$2))+1 -> 4.6386768 | BX7: =AVERAGE(BK7:BV7) -> 7.6892522
A8: Australia | B8: =B7+1 -> 2014 | C8: 396.2575 | D8: 28.467609 | E8: 42.484023 | F8: 0.010763633 | G8: 1.9830444 | H8: 1740.5106 | I8: 8.3109714 | J8: 41.72233 | K8: 28.274059 | L8: 0.29966499 | M8: 9.3 | N8: 4.64 | O8: 20957.854 | P8: 4.7609394 | Q8: 71.620809 | R8: 100 | S8: 99.961476 | T8: 60.783 | U8: 34.4 | V8: 3.4 | W8: 82.3 | X8: 0.4 | Y8: 99.02 | Z8: 99.997733 | AB8: 12.334 | AC8: 12.167 | AE8: =AVERAGE(BJ10,BX10,BB10) -> 4.4218665 | AG8: 73.599998 | AH8: 1.2 | AI8: 23.435439 | AJ8: 44512.596 | AK8: 382.2445 | AL8: 19.723025 | AM8: 58102 | AN8: 91.974377 | AO8: 2.79 | AP8: 7.284 | AQ8: 1.0353828 | AR8: 17.12 | AU8: =((-5*(D6-AU$2))/(AU$1-$AU$2))+6 -> 4.053796 | AV8: =((5*(E6-AV$2))/(AV$1-AV$2))+1 -> 1.2829547 | AW8: =((5*(F6-AW$2))/(AW$1-AW$2))+1 -> 1.8391357 | AX8: =((5*(G6-AX$2))/(AX$1-AX$2))+1 -> 2.1178279 | AY8: =((-5*(H6-AY$2))/(AY$1-AY$2))+6 -> 4.7188379 | AZ8: =((5*(I6-AZ$2))/(AZ$1-AZ$2))+1 -> 3.7001991 | BA8: =((-5*(J6-BA$2))/(BA$1-BA$2))+6 -> 5.2940106 | BB8: =AVERAGE(AU8:BA8) -> 3.2866803 | BC8: =((-5*(K6-BC$2))/(BC$1-BC$2))+6 -> 4.1838288 | BD8: =((-5*(L6-BD$2))/(BD$1-BD$2))+6 -> 4.9498571 | BE8: =((5*(M6-BE$2))/(BE$1-BE$2))+1 -> 1.4400978 | BF8: =((5*(N6-BF$2))/(BF$1-BF$2))+1 -> 2.3113079 | BG8: =((5*(O6-BG$2))/(BG$1-BG$2))+1 -> 1.2013273 | BH8: =((5*(P6-BH$2))/(BH$1-BH$2))+1 -> 2.3865859 | BI8: =((5*(Q6-BI$2))/(BI$1-BI$2))+1 -> 1.2505217 | BJ8: =AVERAGE(BC8:BI8) -> 2.5319324 | BK8: =((5*(R6-BK$2))/(BK$1-BK$2))+1 -> 6 | BL8: =((5*(S6-BL$2))/(BL$1-BL$2))+1 -> 5.9485236 | BM8: =((5*(T6-BM$2))/(BM$1-BM$2))+1 -> 3.774577 | BN8: =((-5*(U6-BN$2))/(BN$1-BN$2))+6 -> 3.0643495 | BO8: =((-5*(V6-BO$2))/(BO$1-BO$2))+6 -> 5.3786982 | BP8: =((5*(W6-BP$2))/(BP$1-BP$2))+1 -> 5.2433631 | BQ8: =((-5*(X6-BQ$2))/(BQ$1-BQ$2))+6 -> 5.7938144 | BR8: =((5*(Y6-BR$2))/(BR$1-BR$2))+1 -> 5.77965 | BS8: =((5*(Z6-BS$2))/(BS$1-BS$2))+1 -> 5.9991777 | BT8: =((-5*(AA6-BT$2))/(BT$1-BT$2))+6 -> 32.725108 | BU8: =((-5*(AB6-BU$2))/(BU$1-BU$2))+6 -> 5.079862 | BV8: =((5*(AC6-BV$2))/(BV$1-BV$2))+1 -> 4.7531807 | BX8: =AVERAGE(BK8:BV8) -> 7.461692
A9: Australia | B9: =B8+1 -> 2015 | C9: 400.5424 | D9: 28.555689 | E9: 41.663932 | F9: 0.0072996431 | G9: 2.0786277 | H9: 1597.3799 | I9: 7.2869216 | J9: 46.482038 | K9: 27.105514 | L9: 0.29641344 | M9: 9.4 | N9: 4.53 | O9: 20658.385 | P9: 3.2376547 | Q9: 146.56143 | R9: 100 | S9: 99.970001 | T9: 61.074 | V9: 3.3 | W9: 82.4 | X9: 0.4 | Y9: 99.37 | Z9: 99.998231 | AA9: 0.92526001 | AB9: 12.025 | AC9: 12.246 | AE9: =AVERAGE(BJ11,BX11,BB11) -> 3.7653051 | AF9: 521 | AG9: 75.550003 | AH9: 1.2 | AI9: 23.331328 | AJ9: 44512.596 | AK9: 402.1245 | AL9: 19.836053 | AM9: 57744 | AN9: 95.105927 | AO9: 2.79 | AP9: 7.313 | AQ9: 0.99075423 | AR9: 17.12 | AU9: =((-5*(D7-AU$2))/(AU$1-$AU$2))+6 -> 4.0394261 | AV9: =((5*(E7-AV$2))/(AV$1-AV$2))+1 -> 1.2575402 | AW9: =((5*(F7-AW$2))/(AW$1-AW$2))+1 -> 1.832043 | AX9: =((5*(G7-AX$2))/(AX$1-AX$2))+1 -> 2.0819991 | AY9: =((-5*(H7-AY$2))/(AY$1-AY$2))+6 -> 4.4661518 | AZ9: =((5*(I7-AZ$2))/(AZ$1-AZ$2))+1 -> 3.5973324 | BA9: =((-5*(J7-BA$2))/(BA$1-BA$2))+6 -> 5.3324917 | BB9: =AVERAGE(AU9:BA9) -> 3.2295692 | BC9: =((-5*(K7-BC$2))/(BC$1-BC$2))+6 -> 4.4672729 | BD9: =((-5*(L7-BD$2))/(BD$1-BD$2))+6 -> 5.0023338 | BE9: =((5*(M7-BE$2))/(BE$1-BE$2))+1 -> 1.49511 | BF9: =((5*(N7-BF$2))/(BF$1-BF$2))+1 -> 2.3010899 | BG9: =((5*(O7-BG$2))/(BG$1-BG$2))+1 -> 1.197879 | BH9: =((5*(P7-BH$2))/(BH$1-BH$2))+1 -> 2.3923375 | BI9: =((5*(Q7-BI$2))/(BI$1-BI$2))+1 -> 1.2102937 | BJ9: =AVERAGE(BC9:BI9) -> 2.5809024 | BK9: =((5*(R7-BK$2))/(BK$1-BK$2))+1 -> 6 | BL9: =((5*(S7-BL$2))/(BL$1-BL$2))+1 -> 5.9530989 | BM9: =((5*(T7-BM$2))/(BM$1-BM$2))+1 -> 3.7195819 | BN9: =((-5*(U7-BN$2))/(BN$1-BN$2))+6 -> 6.02901 | BO9: =((-5*(V7-BO$2))/(BO$1-BO$2))+6 -> 5.408284 | BP9: =((5*(W7-BP$2))/(BP$1-BP$2))+1 -> 5.2741983 | BQ9: =((-5*(X7-BQ$2))/(BQ$1-BQ$2))+6 -> 5.7938144 | BR9: =((5*(Y7-BR$2))/(BR$1-BR$2))+1 -> 5.7861309 | BS9: =((5*(Z7-BS$2))/(BS$1-BS$2))+1 -> 5.9993032 | BT9: =((-5*(AA7-BT$2))/(BT$1-BT$2))+6 -> 32.725108 | BU9: =((-5*(AB7-BU$2))/(BU$1-BU$2))+6 -> 5.1110915 | BV9: =((5*(AC7-BV$2))/(BV$1-BV$2))+1 -> 4.576972 | BX9: =AVERAGE(BK9:BV9) -> 7.6980494
A10: Australia | B10: =B9+1 -> 2016 | C10: 408.5061 | D10: 28.634285 | E10: 40.974079 | F10: 0.011668154 | G10: 2.168721 | H10: 1568.4291 | I10: 5.2762044 | J10: 54.677987 | K10: 26.046667 | L10: 0.294189 | M10: 9.6 | N10: 4.4 | O10: 20338.22 | P10: 4.0809879 | Q10: 130.71485 | R10: 100 | S10: 99.969967 | T10: 61.175 | U10: 33.7 | V10: 3.2 | W10: 82.44878 | X10: 0.4 | Y10: 99.39 | Z10: 99.998729 | AA10: 0.92517 | AB10: 11.317 | AC10: 12.352 | AE10: =AVERAGE(BJ12,BX12,BB12) -> 3.6776688 | AG10: 76.419998 | AH10: 1.2 | AI10: 23.403124 | AJ10: 44512.596 | AK10: 428.5137 | AL10: 19.257867 | AM10: 57885 | AN10: 93.608335 | AO10: 2.79 | AP10: 7.284 | AQ10: 0.93818317 | AR10: 17.12 | AU10: =((-5*(D8-AU$2))/(AU$1-$AU$2))+6 -> 4.0269526 | AV10: =((5*(E8-AV$2))/(AV$1-AV$2))+1 -> 1.273814 | AW10: =((5*(F8-AW$2))/(AW$1-AW$2))+1 -> 1.8333027 | AX10: =((5*(G8-AX$2))/(AX$1-AX$2))+1 -> 2.4198257 | AY10: =((-5*(H8-AY$2))/(AY$1-AY$2))+6 -> 4.4681913 | AZ10: =((5*(I8-AZ$2))/(AZ$1-AZ$2))+1 -> 3.4172057 | BA10: =((-5*(J8-BA$2))/(BA$1-BA$2))+6 -> 5.2473695 | BB10: =AVERAGE(AU10:BA10) -> 3.2409516 | BC10: =((-5*(K8-BC$2))/(BC$1-BC$2))+6 -> 4.586297 | BD10: =((-5*(L8-BD$2))/(BD$1-BD$2))+6 -> 5.0576484 | BE10: =((5*(M8-BE$2))/(BE$1-BE$2))+1 -> 1.5012225 | BF10: =((5*(N8-BF$2))/(BF$1-BF$2))+1 -> 2.25 | BG10: =((5*(O8-BG$2))/(BG$1-BG$2))+1 -> 1.1949383 | BH10: =((5*(P8-BH$2))/(BH$1-BH$2))+1 -> 2.2459944 | BI10: =((5*(Q8-BI$2))/(BI$1-BI$2))+1 -> 1.2249176 | BJ10: =AVERAGE(BC10:BI10) -> 2.5801455 | BK10: =((5*(R8-BK$2))/(BK$1-BK$2))+1 -> 6 | BL10: =((5*(S8-BL$2))/(BL$1-BL$2))+1 -> 5.9800156 | BM10: =((5*(T8-BM$2))/(BM$1-BM$2))+1 -> 3.6626512 | BN10: =((-5*(U8-BN$2))/(BN$1-BN$2))+6 -> 2.9006566 | BO10: =((-5*(V8-BO$2))/(BO$1-BO$2))+6 -> 5.4378698 | BP10: =((5*(W8-BP$2))/(BP$1-BP$2))+1 -> 5.3197169 | BQ10: =((-5*(X8-BQ$2))/(BQ$1-BQ$2))+6 -> 5.7938144 | BR10: =((5*(Y8-BR$2))/(BR$1-BR$2))+1 -> 5.6824368 | BS10: =((5*(Z8-BS$2))/(BS$1-BS$2))+1 -> 5.9994288 | BT10: =((-5*(AA8-BT$2))/(BT$1-BT$2))+6 -> 32.725108 | BU10: =((-5*(AB8-BU$2))/(BU$1-BU$2))+6 -> 5.1612099 | BV10: =((5*(AC8-BV$2))/(BV$1-BV$2))+1 -> 4.6711196 | BX10: =AVERAGE(BK10:BV10) -> 7.4445023
A11: Australia | B11: =B10+1 -> 2017 | C11: 410.8371 | D11: 28.646724 | E11: 42.203732 | F11: 0.0060901655 | G11: 3.803818 | H11: 1679.043 | I11: 6.4506444 | J11: 53.316436 | K11: 24.904209 | L11: 0.28927344 | M11: 9.9 | N11: 4.46 | O11: 20006.028 | P11: 5.0680477 | Q11: 117.7776 | R11: 100 | S11: 99.969938 | T11: 61.537 | V11: 3.2 | W11: 82.5 | X11: 0.4 | Y11: 99.41 | Z11: 99.999228 | AA11: 0.93753999 | AB11: 10.914 | AC11: 12.422 | AE11: =AVERAGE(BJ13,BX13,BB13) -> 3.8056284 | AG11: 77.260002 | AH11: 1.2 | AI11: 23.61036 | AJ11: 44512.596 | AK11: 439.1164 | AL11: 19.890178 | AM11: 57619 | AN11: 94.974186 | AO11: 2.79 | AP11: 7.2721 | AQ11: 0.84586083 | AR11: 17.12 | AU11: =((-5*(D9-AU$2))/(AU$1-$AU$2))+6 -> 4.0135317 | AV11: =((5*(E9-AV$2))/(AV$1-AV$2))+1 -> 1.2627947 | AW11: =((5*(F9-AW$2))/(AW$1-AW$2))+1 -> 1.8313634 | AX11: =((5*(G9-AX$2))/(AX$1-AX$2))+1 -> 2.4551194 | AY11: =((-5*(H9-AY$2))/(AY$1-AY$2))+6 -> 4.5941594 | AZ11: =((5*(I9-AZ$2))/(AZ$1-AZ$2))+1 -> 3.2913126 | BA11: =((-5*(J9-BA$2))/(BA$1-BA$2))+6 -> 5.1500305 | BB11: =AVERAGE(AU11:BA11) -> 3.2283302 | BC11: =((-5*(K9-BC$2))/(BC$1-BC$2))+6 -> 4.6447243 | BD11: =((-5*(L9-BD$2))/(BD$1-BD$2))+6 -> 5.0695863 | BE11: =((5*(M9-BE$2))/(BE$1-BE$2))+1 -> 1.507335 | BF11: =((5*(N9-BF$2))/(BF$1-BF$2))+1 -> 2.2125341 | BG11: =((5*(O9-BG$2))/(BG$1-BG$2))+1 -> 1.1921422 | BH11: =((5*(P9-BH$2))/(BH$1-BH$2))+1 -> 1.8473327 | BI11: =((5*(Q9-BI$2))/(BI$1-BI$2))+1 -> 1.4792454 | BJ11: =AVERAGE(BC11:BI11) -> 2.5647 | BK11: =((5*(R9-BK$2))/(BK$1-BK$2))+1 -> 6 | BL11: =((5*(S9-BL$2))/(BL$1-BL$2))+1 -> 5.9844378 | BM11: =((5*(T9-BM$2))/(BM$1-BM$2))+1 -> 3.6957848 | BN11: =((-5*(U9-BN$2))/(BN$1-BN$2))+6 -> 6.02901 | BO11: =((-5*(V9-BO$2))/(BO$1-BO$2))+6 -> 5.4674556 | BP11: =((5*(W9-BP$2))/(BP$1-BP$2))+1 -> 5.3498179 | BQ11: =((-5*(X9-BQ$2))/(BQ$1-BQ$2))+6 -> 5.7938144 | BR11: =((5*(Y9-BR$2))/(BR$1-BR$2))+1 -> 5.7958522 | BS11: =((5*(Z9-BS$2))/(BS$1-BS$2))+1 -> 5.9995543 | BT11: =((-5*(AA9-BT$2))/(BT$1-BT$2))+6 -> 5.9974001 | BU11: =((-5*(AB9-BU$2))/(BU$1-BU$2))+6 -> 5.2001209 | BV11: =((5*(AC9-BV$2))/(BV$1-BV$2))+1 -> 4.721374 | BX11: =AVERAGE(BK11:BV11) -> 5.5028852
A12: Australia | B12: =B11+1 -> 2018 | C12: 409.2067 | D12: 28.601562 | E12: 43.736065 | F12: 0.013508661 | G12: 3.1940178 | H12: 1806.4501 | I12: 6.0947064 | J12: 54.503066 | K12: 24.893584 | L12: 0.28006391 | M12: 9.8 | N12: 4.37 | O12: 19708.966 | P12: 5.2275206 | Q12: 118.50114 | R12: 100 | S12: 99.969894 | T12: 62.232 | U12: 34.3 | V12: 3.2 | W12: 82.74878 | X12: 0.4 | Y12: 99.43 | Z12: 99.999726 | AA12: 0.96885002 | AB12: 10.551 | AC12: 12.554 | AE12: =AVERAGE(BJ14,BX14,BB14) -> 3.6859841 | AF12: 510 | AG12: 78.330002 | AH12: 1.2 | AI12: 23.712233 | AJ12: 44512.596 | AK12: 428.0391 | AL12: 19.35634 | AM12: 57843 | AN12: 93.282543 | AO12: 2.79 | AP12: 7.228 | AQ12: 0.88473504 | AR12: 17.12 | AU12: =((-5*(D10-AU$2))/(AU$1-$AU$2))+6 -> 4.0015558 | AV12: =((5*(E10-AV$2))/(AV$1-AV$2))+1 -> 1.2535254 | AW12: =((5*(F10-AW$2))/(AW$1-AW$2))+1 -> 1.8338091 | AX12: =((5*(G10-AX$2))/(AX$1-AX$2))+1 -> 2.488386 | AY12: =((-5*(H10-AY$2))/(AY$1-AY$2))+6 -> 4.6196388 | AZ12: =((5*(I10-AZ$2))/(AZ$1-AZ$2))+1 -> 3.0441219 | BA12: =((-5*(J10-BA$2))/(BA$1-BA$2))+6 -> 4.9824183 | BB12: =AVERAGE(AU12:BA12) -> 3.1747793 | BC12: =((-5*(K10-BC$2))/(BC$1-BC$2))+6 -> 4.6976667 | BD12: =((-5*(L10-BD$2))/(BD$1-BD$2))+6 -> 5.0777531 | BE12: =((5*(M10-BE$2))/(BE$1-BE$2))+1 -> 1.5195599 | BF12: =((5*(N10-BF$2))/(BF$1-BF$2))+1 -> 2.1682561 | BG12: =((5*(O10-BG$2))/(BG$1-BG$2))+1 -> 1.1891528 | BH12: =((5*(P10-BH$2))/(BH$1-BH$2))+1 -> 2.068043 | BI12: =((5*(Q10-BI$2))/(BI$1-BI$2))+1 -> 1.4254665 | BJ12: =AVERAGE(BC12:BI12) -> 2.5922712 | BK12: =((5*(R10-BK$2))/(BK$1-BK$2))+1 -> 6 | BL12: =((5*(S10-BL$2))/(BL$1-BL$2))+1 -> 5.98442 | BM12: =((5*(T10-BM$2))/(BM$1-BM$2))+1 -> 3.7072849 | BN12: =((-5*(U10-BN$2))/(BN$1-BN$2))+6 -> 2.9643149 | BO12: =((-5*(V10-BO$2))/(BO$1-BO$2))+6 -> 5.4970414 | BP12: =((5*(W10-BP$2))/(BP$1-BP$2))+1 -> 5.3645014 | BQ12: =((-5*(X10-BQ$2))/(BQ$1-BQ$2))+6 -> 5.7938144 | BR12: =((5*(Y10-BR$2))/(BR$1-BR$2))+1 -> 5.8023331 | BS12: =((5*(Z10-BS$2))/(BS$1-BS$2))+1 -> 5.9996799 | BT12: =((-5*(AA10-BT$2))/(BT$1-BT$2))+6 -> 6 | BU12: =((-5*(AB10-BU$2))/(BU$1-BU$2))+6 -> 5.2892762 | BV12: =((5*(AC10-BV$2))/(BV$1-BV$2))+1 -> 4.7888041 | BX12: =AVERAGE(BK12:BV12) -> 5.2659559
A13: Australia | B13: =B12+1 -> 2019 | C13: 407.8604 | D13: 28.536605 | E13: 46.187502 | F13: 0.0067306717 | G13: 2.7334688 | H13: 1973.365 | I13: 6.2947493 | J13: 60.226085 | L13: 0.27320962 | M13: 10.3 | N13: 4.36 | O13: 19419.908 | P13: 5.7488613 | Q13: 141.36817 | R13: 100 | S13: 99.969854 | T13: 62.655 | V13: 3.2 | W13: 82.9 | X13: 0.4 | Y13: 99.45 | Z13: 100 | AA13: 0.96407002 | AB13: 10.269 | AC13: 12.657 | AE13: =AVERAGE(BJ15,BX15,BB15) -> 3.8362457 | AG13: 79.050003 | AH13: 1.2 | AI13: 24.914546 | AJ13: 44512.596 | AK13: 461.0253 | AM13: 58620 | AN13: 94.028273 | AO13: 2.85 | AP13: 7.2228 | AQ13: 0.88732299 | AR13: 17.12 | AU13: =((-5*(D11-AU$2))/(AU$1-$AU$2))+6 -> 3.9996605 | AV13: =((5*(E11-AV$2))/(AV$1-AV$2))+1 -> 1.2700479 | AW13: =((5*(F11-AW$2))/(AW$1-AW$2))+1 -> 1.8306862 | AX13: =((5*(G11-AX$2))/(AX$1-AX$2))+1 -> 3.0921388 | AY13: =((-5*(H11-AY$2))/(AY$1-AY$2))+6 -> 4.5222884 | AZ13: =((5*(I11-AZ$2))/(AZ$1-AZ$2))+1 -> 3.1885035 | BA13: =((-5*(J11-BA$2))/(BA$1-BA$2))+6 -> 5.0102628 | BB13: =AVERAGE(AU13:BA13) -> 3.2733697 | BC13: =((-5*(K11-BC$2))/(BC$1-BC$2))+6 -> 4.7547896 | BD13: =((-5*(L11-BD$2))/(BD$1-BD$2))+6 -> 5.0958002 | BE13: =((5*(M11-BE$2))/(BE$1-BE$2))+1 -> 1.5378973 | BF13: =((5*(N11-BF$2))/(BF$1-BF$2))+1 -> 2.1886921 | BG13: =((5*(O11-BG$2))/(BG$1-BG$2))+1 -> 1.186051 | BH13: =((5*(P11-BH$2))/(BH$1-BH$2))+1 -> 2.3263683 | BI13: =((5*(Q11-BI$2))/(BI$1-BI$2))+1 -> 1.381561 | BJ13: =AVERAGE(BC13:BI13) -> 2.6387371 | BK13: =((5*(R11-BK$2))/(BK$1-BK$2))+1 -> 6 | BL13: =((5*(S11-BL$2))/(BL$1-BL$2))+1 -> 5.9844049 | BM13: =((5*(T11-BM$2))/(BM$1-BM$2))+1 -> 3.7485027 | BN13: =((-5*(U11-BN$2))/(BN$1-BN$2))+6 -> 6.02901 | BO13: =((-5*(V11-BO$2))/(BO$1-BO$2))+6 -> 5.4970414 | BP13: =((5*(W11-BP$2))/(BP$1-BP$2))+1 -> 5.3799189 | BQ13: =((-5*(X11-BQ$2))/(BQ$1-BQ$2))+6 -> 5.7938144 | BR13: =((5*(Y11-BR$2))/(BR$1-BR$2))+1 -> 5.808814 | BS13: =((5*(Z11-BS$2))/(BS$1-BS$2))+1 -> 5.9998054 | BT13: =((-5*(AA11-BT$2))/(BT$1-BT$2))+6 -> 5.6426718 | BU13: =((-5*(AB11-BU$2))/(BU$1-BU$2))+6 -> 5.3400242 | BV13: =((5*(AC11-BV$2))/(BV$1-BV$2))+1 -> 4.8333333 | BX13: =AVERAGE(BK13:BV13) -> 5.5047784
A14: Australia | B14: =B13+1 -> 2020 | C14: 392.5191 | D14: 28.50885 | E14: 44.664456 | F14: -0.013439774 | G14: 0.45749415 | H14: 2212.1695 | I14: 7.1579708 | J14: 69.321575 | L14: 0.26324791 | M14: 11.2 | N14: 4.44 | O14: 19181.849 | P14: 6.0931587 | Q14: 171.97953 | R14: 100 | S14: 99.969818 | T14: 60.825 | U14: 0.319 | V14: 3.2 | W14: 83.2 | X14: 0.4 | Y14: 99.47 | Z14: 100 | AA14: 0.97929001 | AB14: 9.955 | AC14: 12.727 | AE14: =AVERAGE(BJ16,BX16,BB16) -> 3.7821112 | AG14: 80.050003 | AH14: 1.2 | AI14: 25.048223 | AJ14: 44512.596 | AK14: 469.6708 | AM14: 60377 | AN14: 93.446848 | AO14: 2.85 | AP14: 7.1835 | AQ14: 0.86092546 | AR14: 17.12 | AU14: =((-5*(D12-AU$2))/(AU$1-$AU$2))+6 -> 4.0065419 | AV14: =((5*(E12-AV$2))/(AV$1-AV$2))+1 -> 1.2906374 | AW14: =((5*(F12-AW$2))/(AW$1-AW$2))+1 -> 1.8348395 | AX14: =((5*(G12-AX$2))/(AX$1-AX$2))+1 -> 2.8669726 | AY14: =((-5*(H12-AY$2))/(AY$1-AY$2))+6 -> 4.4101585 | AZ14: =((5*(I12-AZ$2))/(AZ$1-AZ$2))+1 -> 3.1447457 | BA14: =((-5*(J12-BA$2))/(BA$1-BA$2))+6 -> 4.9859955 | BB14: =AVERAGE(AU14:BA14) -> 3.2199844 | BC14: =((-5*(K12-BC$2))/(BC$1-BC$2))+6 -> 4.7553208 | BD14: =((-5*(L12-BD$2))/(BD$1-BD$2))+6 -> 5.1296124 | BE14: =((5*(M12-BE$2))/(BE$1-BE$2))+1 -> 1.5317848 | BF14: =((5*(N12-BF$2))/(BF$1-BF$2))+1 -> 2.1580381 | BG14: =((5*(O12-BG$2))/(BG$1-BG$2))+1 -> 1.1832774 | BH14: =((5*(P12-BH$2))/(BH$1-BH$2))+1 -> 2.3681043 | BI14: =((5*(Q12-BI$2))/(BI$1-BI$2))+1 -> 1.3840165 | BJ14: =AVERAGE(BC14:BI14) -> 2.6443078 | BK14: =((5*(R12-BK$2))/(BK$1-BK$2))+1 -> 6 | BL14: =((5*(S12-BL$2))/(BL$1-BL$2))+1 -> 5.9843822 | BM14: =((5*(T12-BM$2))/(BM$1-BM$2))+1 -> 3.8276365 | BN14: =((-5*(U12-BN$2))/(BN$1-BN$2))+6 -> 2.9097506 | BO14: =((-5*(V12-BO$2))/(BO$1-BO$2))+6 -> 5.4970414 | BP14: =((5*(W12-BP$2))/(BP$1-BP$2))+1 -> 5.4548044 | BQ14: =((-5*(X12-BQ$2))/(BQ$1-BQ$2))+6 -> 5.7938144 | BR14: =((5*(Y12-BR$2))/(BR$1-BR$2))+1 -> 5.8152949 | BS14: =((5*(Z12-BS$2))/(BS$1-BS$2))+1 -> 5.999931 | BT14: =((-5*(AA12-BT$2))/(BT$1-BT$2))+6 -> 4.7382286 | BU14: =((-5*(AB12-BU$2))/(BU$1-BU$2))+6 -> 5.3857352 | BV14: =((5*(AC12-BV$2))/(BV$1-BV$2))+1 -> 4.9173028 | BX14: =AVERAGE(BK14:BV14) -> 5.1936602
A15: Australia | B15: =B14+1 -> 2021 | C15: 384.6772 | D15: 28.419219 | E15: 40.30248 | F15: 0.019673998 | G15: 0.52290941 | H15: 2169.6445 | I15: 6.4177718 | J15: 70.010912 | L15: 0.25265467 | M15: 12.3 | N15: 4.1 | O15: 19154.842 | P15: 13.357875 | Q15: 133.08928 | R15: 100 | S15: 99.969775 | T15: 62.738 | V15: 3.2 | W15: 83.3 | X15: 0.4 | Y15: 99.48 | Z15: 100 | AB15: 9.535 | AC15: 12.727 | AE15: =AVERAGE(BJ17,BX17,BB17) -> 4.6576014 | AF15: 503 | AG15: 81.129997 | AH15: 1.2 | AI15: 24.13027 | AJ15: 44512.596 | AK15: 510.6896 | AM15: 60681.499 | AN15: 91.646805 | AO15: 2.85 | AP15: 7.1621 | AQ15: 0.74456748 | AR15: 17.12 | AU15: =((-5*(D13-AU$2))/(AU$1-$AU$2))+6 -> 4.0164395 | AV15: =((5*(E13-AV$2))/(AV$1-AV$2))+1 -> 1.3235766 | AW15: =((5*(F13-AW$2))/(AW$1-AW$2))+1 -> 1.8310448 | AX15: =((5*(G13-AX$2))/(AX$1-AX$2))+1 -> 2.6969168 | AY15: =((-5*(H13-AY$2))/(AY$1-AY$2))+6 -> 4.2632581 | AZ15: =((5*(I13-AZ$2))/(AZ$1-AZ$2))+1 -> 3.1693383 | BA15: =((-5*(J13-BA$2))/(BA$1-BA$2))+6 -> 4.8689562 | BB15: =AVERAGE(AU15:BA15) -> 3.1670758 | BC15: =((-5*(K13-BC$2))/(BC$1-BC$2))+6 -> 6 | BD15: =((-5*(L13-BD$2))/(BD$1-BD$2))+6 -> 5.1547774 | BE15: =((5*(M13-BE$2))/(BE$1-BE$2))+1 -> 1.5623472 | BF15: =((5*(N13-BF$2))/(BF$1-BF$2))+1 -> 2.1546322 | BG15: =((5*(O13-BG$2))/(BG$1-BG$2))+1 -> 1.1805784 | BH15: =((5*(P13-BH$2))/(BH$1-BH$2))+1 -> 2.5045453 | BI15: =((5*(Q13-BI$2))/(BI$1-BI$2))+1 -> 1.4616209 | BJ15: =AVERAGE(BC15:BI15) -> 2.8597859 | BK15: =((5*(R13-BK$2))/(BK$1-BK$2))+1 -> 6 | BL15: =((5*(S13-BL$2))/(BL$1-BL$2))+1 -> 5.9843618 | BM15: =((5*(T13-BM$2))/(BM$1-BM$2))+1 -> 3.8757999 | BN15: =((-5*(U13-BN$2))/(BN$1-BN$2))+6 -> 6.02901 | BO15: =((-5*(V13-BO$2))/(BO$1-BO$2))+6 -> 5.4970414 | BP15: =((5*(W13-BP$2))/(BP$1-BP$2))+1 -> 5.500323 | BQ15: =((-5*(X13-BQ$2))/(BQ$1-BQ$2))+6 -> 5.7938144 | BR15: =((5*(Y13-BR$2))/(BR$1-BR$2))+1 -> 5.8217758 | BS15: =((5*(Z13-BS$2))/(BS$1-BS$2))+1 -> 6 | BT15: =((-5*(AA13-BT$2))/(BT$1-BT$2))+6 -> 4.8763069 | BU15: =((-5*(AB13-BU$2))/(BU$1-BU$2))+6 -> 5.4212462 | BV15: =((5*(AC13-BV$2))/(BV$1-BV$2))+1 -> 4.9828244 | BX15: =AVERAGE(BK15:BV15) -> 5.4818753
A16: Australia | B16: =B15+1 -> 2022 | C16: 374.8785 | D16: 28.189373 | E16: 45.82177 | F16: 0.029241006 | G16: 0.69450396 | H16: 1564.5371 | J16: 58.046696 | L16: 0.23619847 | N16: 4.12 | R16: 100 | S16: 99.969731 | T16: 64.354 | V16: 3.2 | W16: 83.2 | X16: 0.4 | Y16: 99.5 | Z16: 100 | AB16: 8.917 | AC16: 12.727 | AE16: =AVERAGE(BJ18,BX18,BB18) -> 4.4430322 | AF16: 487 | AG16: 81.669998 | AH16: 1.2 | AI16: 23.179486 | AJ16: 44512.596 | AM16: 59407.89 | AN16: 93.81476 | AO16: 2.85 | AP16: 7.0946 | AR16: 17.12 | AU16: =((-5*(D14-AU$2))/(AU$1-$AU$2))+6 -> 4.0206686 | AV16: =((5*(E14-AV$2))/(AV$1-AV$2))+1 -> 1.3031119 | AW16: =((5*(F14-AW$2))/(AW$1-AW$2))+1 -> 1.8197524 | AX16: =((5*(G14-AX$2))/(AX$1-AX$2))+1 -> 1.8565224 | AY16: =((-5*(H14-AY$2))/(AY$1-AY$2))+6 -> 4.0530883 | AZ16: =((5*(I14-AZ$2))/(AZ$1-AZ$2))+1 -> 3.2754598 | BA16: =((-5*(J14-BA$2))/(BA$1-BA$2))+6 -> 4.6829478 | BB16: =AVERAGE(AU16:BA16) -> 3.0016502 | BC16: =((-5*(K14-BC$2))/(BC$1-BC$2))+6 -> 6 | BD16: =((-5*(L14-BD$2))/(BD$1-BD$2))+6 -> 5.1913511 | BE16: =((5*(M14-BE$2))/(BE$1-BE$2))+1 -> 1.6173594 | BF16: =((5*(N14-BF$2))/(BF$1-BF$2))+1 -> 2.1818801 | BG16: =((5*(O14-BG$2))/(BG$1-BG$2))+1 -> 1.1783556 | BH16: =((5*(P14-BH$2))/(BH$1-BH$2))+1 -> 2.594652 | BI16: =((5*(Q14-BI$2))/(BI$1-BI$2))+1 -> 1.5655075 | BJ16: =AVERAGE(BC16:BI16) -> 2.904158 | BK16: =((5*(R14-BK$2))/(BK$1-BK$2))+1 -> 6 | BL16: =((5*(S14-BL$2))/(BL$1-BL$2))+1 -> 5.9843427 | BM16: =((5*(T14-BM$2))/(BM$1-BM$2))+1 -> 3.6674333 | BN16: =((-5*(U14-BN$2))/(BN$1-BN$2))+6 -> 6 | BO16: =((-5*(V14-BO$2))/(BO$1-BO$2))+6 -> 5.4970414 | BP16: =((5*(W14-BP$2))/(BP$1-BP$2))+1 -> 5.5906261 | BQ16: =((-5*(X14-BQ$2))/(BQ$1-BQ$2))+6 -> 5.7938144 | BR16: =((5*(Y14-BR$2))/(BR$1-BR$2))+1 -> 5.8282566 | BS16: =((5*(Z14-BS$2))/(BS$1-BS$2))+1 -> 6 | BT16: =((-5*(AA14-BT$2))/(BT$1-BT$2))+6 -> 4.4366517 | BU16: =((-5*(AB14-BU$2))/(BU$1-BU$2))+6 -> 5.4607868 | BV16: =((5*(AC14-BV$2))/(BV$1-BV$2))+1 -> 5.0273537 | BX16: =AVERAGE(BK16:BV16) -> 5.4405256
A17: Australia | B17: =B16+1 -> 2023 | C17: 373.6164 | D17: 27.916839 | E17: 49.225184 | F17: 0.0094101457 | G17: 0.64528262 | L17: 0.22757031 | R17: 100 | T17: 64.707 | X17: 0.4 | Y17: 99.52 | Z17: 100 | AB17: 8.958 | AE17: =AVERAGE(BJ19,BX19,BB19) -> 2.1689142 | AG17: 78.963837 | AI17: 23.179486 | AJ17: 44512.596 | AP17: 7.0569 | AU17: =((-5*(D15-AU$2))/(AU$1-$AU$2))+6 -> 4.0343259 | AV17: =((5*(E15-AV$2))/(AV$1-AV$2))+1 -> 1.2445013 | AW17: =((5*(F15-AW$2))/(AW$1-AW$2))+1 -> 1.8382912 | AX17: =((5*(G15-AX$2))/(AX$1-AX$2))+1 -> 1.8806768 | AY17: =((-5*(H15-AY$2))/(AY$1-AY$2))+6 -> 4.0905141 | AZ17: =((5*(I15-AZ$2))/(AZ$1-AZ$2))+1 -> 3.1844623 | BA17: =((-5*(J15-BA$2))/(BA$1-BA$2))+6 -> 4.6688504 | BB17: =AVERAGE(AU17:BA17) -> 2.9916603 | BC17: =((-5*(K15-BC$2))/(BC$1-BC$2))+6 -> 6 | BD17: =((-5*(L15-BD$2))/(BD$1-BD$2))+6 -> 5.2302434 | BE17: =((5*(M15-BE$2))/(BE$1-BE$2))+1 -> 1.6845966 | BF17: =((5*(N15-BF$2))/(BF$1-BF$2))+1 -> 2.0660763 | BG17: =((5*(O15-BG$2))/(BG$1-BG$2))+1 -> 1.1781034 | BH17: =((5*(P15-BH$2))/(BH$1-BH$2))+1 -> 4.4959147 | BI17: =((5*(Q15-BI$2))/(BI$1-BI$2))+1 -> 1.4335247 | BJ17: =AVERAGE(BC17:BI17) -> 3.1554942 | BK17: =((5*(R15-BK$2))/(BK$1-BK$2))+1 -> 6 | BL17: =((5*(S15-BL$2))/(BL$1-BL$2))+1 -> 5.9843204 | BM17: =((5*(T15-BM$2))/(BM$1-BM$2))+1 -> 3.8852504 | BN17: =((-5*(U15-BN$2))/(BN$1-BN$2))+6 -> 6.02901 | BO17: =((-5*(V15-BO$2))/(BO$1-BO$2))+6 -> 5.4970414 | BP17: =((5*(W15-BP$2))/(BP$1-BP$2))+1 -> 5.6207271 | BQ17: =((-5*(X15-BQ$2))/(BQ$1-BQ$2))+6 -> 5.7938144 | BR17: =((5*(Y15-BR$2))/(BR$1-BR$2))+1 -> 5.8314971 | BS17: =((5*(Z15-BS$2))/(BS$1-BS$2))+1 -> 6 | BT17: =((-5*(AA15-BT$2))/(BT$1-BT$2))+6 -> 32.725108 | BU17: =((-5*(AB15-BU$2))/(BU$1-BU$2))+6 -> 5.5136755 | BV17: =((5*(AC15-BV$2))/(BV$1-BV$2))+1 -> 5.0273537 | BX17: =AVERAGE(BK17:BV17) -> 7.8256498
A18: Australia | B18: =B17+1 -> 2024 | R18: 100 | Z18: 100 | AE18: =AVERAGE(BJ20,BX20,BB20) -> 1.3047693 | AJ18: 44512.596 | AU18: =((-5*(D16-AU$2))/(AU$1-$AU$2))+6 -> 4.0693478 | AV18: =((5*(E16-AV$2))/(AV$1-AV$2))+1 -> 1.3186624 | AW18: =((5*(F16-AW$2))/(AW$1-AW$2))+1 -> 1.8436473 | AX18: =((5*(G16-AX$2))/(AX$1-AX$2))+1 -> 1.9440373 | AY18: =((-5*(H16-AY$2))/(AY$1-AY$2))+6 -> 4.6230641 | AZ18: =((5*(I16-AZ$2))/(AZ$1-AZ$2))+1 -> 2.3954833 | BA18: =((-5*(J16-BA$2))/(BA$1-BA$2))+6 -> 4.9135261 | BB18: =AVERAGE(AU18:BA18) -> 3.0153955 | BC18: =((-5*(K16-BC$2))/(BC$1-BC$2))+6 -> 6 | BD18: =((-5*(L16-BD$2))/(BD$1-BD$2))+6 -> 5.2906611 | BE18: =((5*(M16-BE$2))/(BE$1-BE$2))+1 -> 0.93276284 | BF18: =((5*(N16-BF$2))/(BF$1-BF$2))+1 -> 2.0728883 | BG18: =((5*(O16-BG$2))/(BG$1-BG$2))+1 -> 0.99925274 | BH18: =((5*(P16-BH$2))/(BH$1-BH$2))+1 -> 1 | BI18: =((5*(Q16-BI$2))/(BI$1-BI$2))+1 -> 0.9818562 | BJ18: =AVERAGE(BC18:BI18) -> 2.468203 | BK18: =((5*(R16-BK$2))/(BK$1-BK$2))+1 -> 6 | BL18: =((5*(S16-BL$2))/(BL$1-BL$2))+1 -> 5.984298 | BM18: =((5*(T16-BM$2))/(BM$1-BM$2))+1 -> 4.0692506 | BN18: =((-5*(U16-BN$2))/(BN$1-BN$2))+6 -> 6.02901 | BO18: =((-5*(V16-BO$2))/(BO$1-BO$2))+6 -> 5.4970414 | BP18: =((5*(W16-BP$2))/(BP$1-BP$2))+1 -> 5.5906261 | BQ18: =((-5*(X16-BQ$2))/(BQ$1-BQ$2))+6 -> 5.7938144 | BR18: =((5*(Y16-BR$2))/(BR$1-BR$2))+1 -> 5.837978 | BS18: =((5*(Z16-BS$2))/(BS$1-BS$2))+1 -> 6 | BT18: =((-5*(AA16-BT$2))/(BT$1-BT$2))+6 -> 32.725108 | BU18: =((-5*(AB16-BU$2))/(BU$1-BU$2))+6 -> 5.5914975 | BV18: =((5*(AC16-BV$2))/(BV$1-BV$2))+1 -> 5.0273537 | BX18: =AVERAGE(BK18:BV18) -> 7.8454981
A19: Australia | B19: =B18+1 -> 2025 | R19: 100 | Z19: 100 | AE19: =AVERAGE(BJ21,BX21,BB21) -> 1.3047693 | AJ19: 44512.596 | AU19: =((-5*(D17-AU$2))/(AU$1-$AU$2))+6 -> 4.1108743 | AV19: =((5*(E17-AV$2))/(AV$1-AV$2))+1 -> 1.3643931 | AW19: =((5*(F17-AW$2))/(AW$1-AW$2))+1 -> 1.8325449 | AX19: =((5*(G17-AX$2))/(AX$1-AX$2))+1 -> 1.9258626 | AY19: =((-5*(H17-AY$2))/(AY$1-AY$2))+6 -> 6 | AZ19: =((5*(I17-AZ$2))/(AZ$1-AZ$2))+1 -> 2.3954833 | BA19: =((-5*(J17-BA$2))/(BA$1-BA$2))+6 -> 6.1006171 | BB19: =AVERAGE(AU19:BA19) -> 3.3899679 | BC19: =((-5*(K17-BC$2))/(BC$1-BC$2))+6 -> 6 | BD19: =((-5*(L17-BD$2))/(BD$1-BD$2))+6 -> 5.3223388 | BE19: =((5*(M17-BE$2))/(BE$1-BE$2))+1 -> 0.93276284 | BF19: =((5*(N17-BF$2))/(BF$1-BF$2))+1 -> 0.66961853 | BG19: =((5*(O17-BG$2))/(BG$1-BG$2))+1 -> 0.99925274 | BH19: =((5*(P17-BH$2))/(BH$1-BH$2))+1 -> 1 | BI19: =((5*(Q17-BI$2))/(BI$1-BI$2))+1 -> 0.9818562 | BJ19: =AVERAGE(BC19:BI19) -> 2.2722613 | BK19: =((5*(R17-BK$2))/(BK$1-BK$2))+1 -> 6 | BL19: =((5*(S17-BL$2))/(BL$1-BL$2))+1 -> -45.87567 | BM19: =((5*(T17-BM$2))/(BM$1-BM$2))+1 -> 4.1094437 | BN19: =((-5*(U17-BN$2))/(BN$1-BN$2))+6 -> 6.02901 | BO19: =((-5*(V17-BO$2))/(BO$1-BO$2))+6 -> 6.443787 | BP19: =((5*(W17-BP$2))/(BP$1-BP$2))+1 -> -19.453424 | BQ19: =((-5*(X17-BQ$2))/(BQ$1-BQ$2))+6 -> 5.7938144 | BR19: =((5*(Y17-BR$2))/(BR$1-BR$2))+1 -> 5.8444588 | BS19: =((5*(Z17-BS$2))/(BS$1-BS$2))+1 -> 6 | BT19: =((-5*(AA17-BT$2))/(BT$1-BT$2))+6 -> 32.725108 | BU19: =((-5*(AB17-BU$2))/(BU$1-BU$2))+6 -> 5.5863346 | BV19: =((5*(AC17-BV$2))/(BV$1-BV$2))+1 -> -3.0687023 | BX19: =AVERAGE(BK19:BV19) -> 0.84451331
A20: Austria | B20: 2008 | C20: 75.2369 | D20: 22.600561 | E20: 102.7437 | F20: 0.011362113 | G20: 2.3694427 | H20: 1068.9996 | I20: 16.389525 | J20: 72.410468 | K20: 99.148298 | L20: 0.20518561 | M20: 29.7 | N20: 3.15 | O20: 6609.3885 | P20: 0.25818187 | Q20: 104.4144 | R20: 100 | S20: 99.999998 | T20: 57.558 | U20: 30.4 | V20: 3.8 | W20: 80.431707 | X20: 0.4 | Y20: 99.95 | Z20: 99.989327 | AA20: 0.96560001 | AB20: 14.078 | AC20: 11.468 | AE20: =AVERAGE(BJ22,BX22,BB22) -> 3.5777449 | AG20: 72.470001 | AI20: 20.912248 | AJ20: 37553.092 | AK20: 564653 | AL20: 24.322753 | AM20: 62081 | AN20: 92.66891 | AO20: 1.21 | AQ20: 0.69702059 | AR20: 19.07 | AU20: =((-5*(D18-AU$2))/(AU$1-$AU$2))+6 -> 8.3646123 | AV20: =((5*(E18-AV$2))/(AV$1-AV$2))+1 -> 0.70296827 | AW20: =((5*(F18-AW$2))/(AW$1-AW$2))+1 -> 1.8272767 | AX20: =((5*(G18-AX$2))/(AX$1-AX$2))+1 -> 1.6875946 | AY20: =((-5*(H18-AY$2))/(AY$1-AY$2))+6 -> 6 | AZ20: =((5*(I18-AZ$2))/(AZ$1-AZ$2))+1 -> 2.3954833 | BA20: =((-5*(J18-BA$2))/(BA$1-BA$2))+6 -> 6.1006171 | BB20: =AVERAGE(AU20:BA20) -> 3.8683646 | BC20: =((-5*(K18-BC$2))/(BC$1-BC$2))+6 -> 6 | BD20: =((-5*(L18-BD$2))/(BD$1-BD$2))+6 -> 6.1578467 | BE20: =((5*(M18-BE$2))/(BE$1-BE$2))+1 -> 0.93276284 | BF20: =((5*(N18-BF$2))/(BF$1-BF$2))+1 -> 0.66961853 | BG20: =((5*(O18-BG$2))/(BG$1-BG$2))+1 -> 0.99925274 | BH20: =((5*(P18-BH$2))/(BH$1-BH$2))+1 -> 1 | BI20: =((5*(Q18-BI$2))/(BI$1-BI$2))+1 -> 0.9818562 | BJ20: =AVERAGE(BC20:BI20) -> 2.3916196 | BK20: =((5*(R18-BK$2))/(BK$1-BK$2))+1 -> 6 | BL20: =((5*(S18-BL$2))/(BL$1-BL$2))+1 -> -45.87567 | BM20: =((5*(T18-BM$2))/(BM$1-BM$2))+1 -> -3.2581923 | BN20: =((-5*(U18-BN$2))/(BN$1-BN$2))+6 -> 6.02901 | BO20: =((-5*(V18-BO$2))/(BO$1-BO$2))+6 -> 6.443787 | BP20: =((5*(W18-BP$2))/(BP$1-BP$2))+1 -> -19.453424 | BQ20: =((-5*(X18-BQ$2))/(BQ$1-BQ$2))+6 -> 6 | BR20: =((5*(Y18-BR$2))/(BR$1-BR$2))+1 -> -26.404407 | BS20: =((5*(Z18-BS$2))/(BS$1-BS$2))+1 -> 6 | BT20: =((-5*(AA18-BT$2))/(BT$1-BT$2))+6 -> 32.725108 | BU20: =((-5*(AB18-BU$2))/(BU$1-BU$2))+6 -> 6.7143757 | BV20: =((5*(AC18-BV$2))/(BV$1-BV$2))+1 -> -3.0687023 | BX20: =AVERAGE(BK20:BV20) -> -2.3456763
A21: Austria | B21: =B20+1 -> 2009 | C21: 68.0563 | D21: 22.26304 | E21: 87.600493 | F21: -0.038384931 | G21: 0.35740958 | H21: 1099.5941 | I21: 12.271648 | J21: 83.846851 | K21: 99 | L21: 0.19250652 | M21: 31.3 | N21: 3.12 | O21: 6592.0977 | P21: 0.16759974 | Q21: 100.98254 | R21: 100 | S21: 100 | T21: 57.107 | U21: 31.5 | V21: 3.7 | W21: 80.331707 | X21: 0.5 | Y21: 99.94 | Z21: 99.987572 | AA21: 0.96524 | AB21: 13.233 | AC21: 11.674 | AE21: =AVERAGE(BJ23,BX23,BB23) -> 3.5034549 | AF21: 511 | AG21: 75.809998 | AI21: 21.189422 | AJ21: 35583.929 | AK21: 395.7118 | AL21: 21.681013 | AM21: 63135 | AN21: 87.115678 | AO21: 1.21 | AQ21: 0.61129563 | AR21: 19.07 | AU21: =((-5*(D19-AU$2))/(AU$1-$AU$2))+6 -> 8.3646123 | AV21: =((5*(E19-AV$2))/(AV$1-AV$2))+1 -> 0.70296827 | AW21: =((5*(F19-AW$2))/(AW$1-AW$2))+1 -> 1.8272767 | AX21: =((5*(G19-AX$2))/(AX$1-AX$2))+1 -> 1.6875946 | AY21: =((-5*(H19-AY$2))/(AY$1-AY$2))+6 -> 6 | AZ21: =((5*(I19-AZ$2))/(AZ$1-AZ$2))+1 -> 2.3954833 | BA21: =((-5*(J19-BA$2))/(BA$1-BA$2))+6 -> 6.1006171 | BB21: =AVERAGE(AU21:BA21) -> 3.8683646 | BC21: =((-5*(K19-BC$2))/(BC$1-BC$2))+6 -> 6 | BD21: =((-5*(L19-BD$2))/(BD$1-BD$2))+6 -> 6.1578467 | BE21: =((5*(M19-BE$2))/(BE$1-BE$2))+1 -> 0.93276284 | BF21: =((5*(N19-BF$2))/(BF$1-BF$2))+1 -> 0.66961853 | BG21: =((5*(O19-BG$2))/(BG$1-BG$2))+1 -> 0.99925274 | BH21: =((5*(P19-BH$2))/(BH$1-BH$2))+1 -> 1 | BI21: =((5*(Q19-BI$2))/(BI$1-BI$2))+1 -> 0.9818562 | BJ21: =AVERAGE(BC21:BI21) -> 2.3916196 | BK21: =((5*(R19-BK$2))/(BK$1-BK$2))+1 -> 6 | BL21: =((5*(S19-BL$2))/(BL$1-BL$2))+1 -> -45.87567 | BM21: =((5*(T19-BM$2))/(BM$1-BM$2))+1 -> -3.2581923 | BN21: =((-5*(U19-BN$2))/(BN$1-BN$2))+6 -> 6.02901 | BO21: =((-5*(V19-BO$2))/(BO$1-BO$2))+6 -> 6.443787 | BP21: =((5*(W19-BP$2))/(BP$1-BP$2))+1 -> -19.453424 | BQ21: =((-5*(X19-BQ$2))/(BQ$1-BQ$2))+6 -> 6 | BR21: =((5*(Y19-BR$2))/(BR$1-BR$2))+1 -> -26.404407 | BS21: =((5*(Z19-BS$2))/(BS$1-BS$2))+1 -> 6 | BT21: =((-5*(AA19-BT$2))/(BT$1-BT$2))+6 -> 32.725108 | BU21: =((-5*(AB19-BU$2))/(BU$1-BU$2))+6 -> 6.7143757 | BV21: =((5*(AC19-BV$2))/(BV$1-BV$2))+1 -> -3.0687023 | BX21: =AVERAGE(BK21:BV21) -> -2.3456763
A22: Austria | B22: =B21+1 -> 2010 | C22: 73.7958 | D22: 21.950481 | E22: 99.644883 | F22: 0.015645336 | G22: 0.35352401 | H22: 1124.4999 | I22: 12.952806 | J22: 86.324831 | K22: 99 | L22: 0.20503247 | M22: 31.1 | N22: 3.26 | O22: 6576.2697 | P22: 0.21629138 | Q22: 103.12966 | R22: 100 | S22: 100 | T22: 57.343 | U22: 30.3 | V22: 3.6 | W22: 80.580488 | X22: 0.4 | Y22: 99.94 | Z22: 99.985834 | AA22: 0.96872002 | AB22: 12.908 | AC22: 11.715 | AE22: =AVERAGE(BJ24,BX24,BB24) -> 3.5229458 | AG22: 76.559998 | AH22: 1.0393014 | AI22: 21.204328 | AJ22: 36171.812 | AK22: 408.4862 | AL22: 25.446376 | AM22: 62831 | AN22: 94.573729 | AO22: 1.21 | AQ22: 0.72941824 | AR22: 19.07 | AU22: =((-5*(D20-AU$2))/(AU$1-$AU$2))+6 -> 4.920925 | AV22: =((5*(E20-AV$2))/(AV$1-AV$2))+1 -> 2.0835063 | AW22: =((5*(F20-AW$2))/(AW$1-AW$2))+1 -> 1.8336377 | AX22: =((5*(G20-AX$2))/(AX$1-AX$2))+1 -> 2.5625016 | AY22: =((-5*(H20-AY$2))/(AY$1-AY$2))+6 -> 5.0591824 | AZ22: =((5*(I20-AZ$2))/(AZ$1-AZ$2))+1 -> 4.4103554 | BA22: =((-5*(J20-BA$2))/(BA$1-BA$2))+6 -> 4.619778 | BB22: =AVERAGE(AU22:BA22) -> 3.6414124 | BC22: =((-5*(K20-BC$2))/(BC$1-BC$2))+6 -> 1.0425851 | BD22: =((-5*(L20-BD$2))/(BD$1-BD$2))+6 -> 5.4045226 | BE22: =((5*(M20-BE$2))/(BE$1-BE$2))+1 -> 2.7481663 | BF22: =((5*(N20-BF$2))/(BF$1-BF$2))+1 -> 1.7425068 | BG22: =((5*(O20-BG$2))/(BG$1-BG$2))+1 -> 1.0609653 | BH22: =((5*(P20-BH$2))/(BH$1-BH$2))+1 -> 1.0675693 | BI22: =((5*(Q20-BI$2))/(BI$1-BI$2))+1 -> 1.33621 | BJ22: =AVERAGE(BC22:BI22) -> 2.0575036 | BK22: =((5*(R20-BK$2))/(BK$1-BK$2))+1 -> 6 | BL22: =((5*(S20-BL$2))/(BL$1-BL$2))+1 -> 5.9999991 | BM22: =((5*(T20-BM$2))/(BM$1-BM$2))+1 -> 3.2954478 | BN22: =((-5*(U20-BN$2))/(BN$1-BN$2))+6 -> 3.2644186 | BO22: =((-5*(V20-BO$2))/(BO$1-BO$2))+6 -> 5.3195266 | BP22: =((5*(W20-BP$2))/(BP$1-BP$2))+1 -> 4.7573417 | BQ22: =((-5*(X20-BQ$2))/(BQ$1-BQ$2))+6 -> 5.7938144 | BR22: =((5*(Y20-BR$2))/(BR$1-BR$2))+1 -> 5.9837978 | BS22: =((5*(Z20-BS$2))/(BS$1-BS$2))+1 -> 5.997311 | BT22: =((-5*(AA20-BT$2))/(BT$1-BT$2))+6 -> 4.8321105 | BU22: =((-5*(AB20-BU$2))/(BU$1-BU$2))+6 -> 4.9415957 | BV22: =((5*(AC20-BV$2))/(BV$1-BV$2))+1 -> 4.2264631 | BX22: =AVERAGE(BK22:BV22) -> 5.0343189
A23: Austria | B23: =B22+1 -> 2011 | C23: 72.1947 | D23: 21.659739 | E23: 105.7751 | F23: 0.025811032 | G23: 0.34420932 | H23: 1122.9581 | I23: 13.464867 | J23: 86.242002 | K23: 98.451542 | L23: 0.194879 | M23: 31.6 | N23: 3.07 | O23: 6554.1396 | P23: 0.24469049 | Q23: 107.34488 | R23: 100 | S23: 99.999999 | T23: 57.558 | U23: 30.8 | V23: 3.5 | W23: 80.982927 | X23: 0.4 | Y23: 99.93 | Z23: 99.984112 | AA23: 0.97008002 | AB23: 12.358 | AC23: 11.711 | AE23: =AVERAGE(BJ25,BX25,BB25) -> 3.5389715 | AG23: 76.43 | AH23: 0.42038425 | AI23: 21.147973 | AJ23: 36601.337 | AK23: 406.3002 | AL23: 26.25585 | AM23: 62159 | AN23: 93.32737 | AO23: 1.21 | AP23: 7.227316 | AQ23: 0.91762805 | AR23: 19.07 | AU23: =((-5*(D21-AU$2))/(AU$1-$AU$2))+6 -> 4.9723537 | AV23: =((5*(E21-AV$2))/(AV$1-AV$2))+1 -> 1.8800313 | AW23: =((5*(F21-AW$2))/(AW$1-AW$2))+1 -> 1.8057868 | AX23: =((5*(G21-AX$2))/(AX$1-AX$2))+1 -> 1.8195666 | AY23: =((-5*(H21-AY$2))/(AY$1-AY$2))+6 -> 5.0322565 | AZ23: =((5*(I21-AZ$2))/(AZ$1-AZ$2))+1 -> 3.9041178 | BA23: =((-5*(J21-BA$2))/(BA$1-BA$2))+6 -> 4.3858969 | BB23: =AVERAGE(AU23:BA23) -> 3.4000014 | BC23: =((-5*(K21-BC$2))/(BC$1-BC$2))+6 -> 1.05 | BD23: =((-5*(L21-BD$2))/(BD$1-BD$2))+6 -> 5.451073 | BE23: =((5*(M21-BE$2))/(BE$1-BE$2))+1 -> 2.8459658 | BF23: =((5*(N21-BF$2))/(BF$1-BF$2))+1 -> 1.7322888 | BG23: =((5*(O21-BG$2))/(BG$1-BG$2))+1 -> 1.0608038 | BH23: =((5*(P21-BH$2))/(BH$1-BH$2))+1 -> 1.0438628 | BI23: =((5*(Q21-BI$2))/(BI$1-BI$2))+1 -> 1.3245632 | BJ23: =AVERAGE(BC23:BI23) -> 2.0726511 | BK23: =((5*(R21-BK$2))/(BK$1-BK$2))+1 -> 6 | BL23: =((5*(S21-BL$2))/(BL$1-BL$2))+1 -> 6 | BM23: =((5*(T21-BM$2))/(BM$1-BM$2))+1 -> 3.2440963 | BN23: =((-5*(U21-BN$2))/(BN$1-BN$2))+6 -> 3.1643841 | BO23: =((-5*(V21-BO$2))/(BO$1-BO$2))+6 -> 5.3491124 | BP23: =((5*(W21-BP$2))/(BP$1-BP$2))+1 -> 4.7272407 | BQ23: =((-5*(X21-BQ$2))/(BQ$1-BQ$2))+6 -> 5.742268 | BR23: =((5*(Y21-BR$2))/(BR$1-BR$2))+1 -> 5.9805574 | BS23: =((5*(Z21-BS$2))/(BS$1-BS$2))+1 -> 5.996869 | BT23: =((-5*(AA21-BT$2))/(BT$1-BT$2))+6 -> 4.84251 | BU23: =((-5*(AB21-BU$2))/(BU$1-BU$2))+6 -> 5.0480028 | BV23: =((5*(AC21-BV$2))/(BV$1-BV$2))+1 -> 4.3575064 | BX23: =AVERAGE(BK23:BV23) -> 5.0377123
A24: Austria | B24: =B23+1 -> 2012 | C24: 69.0271 | D24: 21.447748 | E24: 105.84079 | F24: 0.0017048863 | G24: 0.13003922 | H24: 1082.5479 | I24: 12.654876 | J24: 91.19095 | K24: 99.257171 | L24: 0.18516523 | M24: 34.4 | N24: 3.04 | O24: 6524.3249 | P24: 0.23850822 | Q24: 109.25036 | R24: 100 | S24: 99.999997 | T24: 57.67 | U24: 30.5 | V24: 3.3 | W24: 80.936585 | X24: 0.5 | Y24: 99.93 | Z24: 99.982308 | AA24: 0.97157001 | AB24: 11.919 | AC24: 11.752 | AE24: =AVERAGE(BJ26,BX26,BB26) -> 3.5379248 | AG24: 76.980003 | AH24: 0.42087026 | AI24: 21.46044 | AJ24: 36290.759 | AK24: 407.8979 | AL24: 24.912509 | AM24: 62515 | AN24: 93.753634 | AO24: 1.21 | AQ24: 0.96089553 | AR24: 19.07 | AU24: =((-5*(D22-AU$2))/(AU$1-$AU$2))+6 -> 5.0199788 | AV24: =((5*(E22-AV$2))/(AV$1-AV$2))+1 -> 2.0418683 | AW24: =((5*(F22-AW$2))/(AW$1-AW$2))+1 -> 1.8360357 | AX24: =((5*(G22-AX$2))/(AX$1-AX$2))+1 -> 1.8181319 | AY24: =((-5*(H22-AY$2))/(AY$1-AY$2))+6 -> 5.0103371 | AZ24: =((5*(I22-AZ$2))/(AZ$1-AZ$2))+1 -> 3.987857 | BA24: =((-5*(J22-BA$2))/(BA$1-BA$2))+6 -> 4.3352206 | BB24: =AVERAGE(AU24:BA24) -> 3.4356328 | BC24: =((-5*(K22-BC$2))/(BC$1-BC$2))+6 -> 1.05 | BD24: =((-5*(L22-BD$2))/(BD$1-BD$2))+6 -> 5.4050848 | BE24: =((5*(M22-BE$2))/(BE$1-BE$2))+1 -> 2.8337408 | BF24: =((5*(N22-BF$2))/(BF$1-BF$2))+1 -> 1.7799728 | BG24: =((5*(O22-BG$2))/(BG$1-BG$2))+1 -> 1.060656 | BH24: =((5*(P22-BH$2))/(BH$1-BH$2))+1 -> 1.056606 | BI24: =((5*(Q22-BI$2))/(BI$1-BI$2))+1 -> 1.3318499 | BJ24: =AVERAGE(BC24:BI24) -> 2.0739872 | BK24: =((5*(R22-BK$2))/(BK$1-BK$2))+1 -> 6 | BL24: =((5*(S22-BL$2))/(BL$1-BL$2))+1 -> 6 | BM24: =((5*(T22-BM$2))/(BM$1-BM$2))+1 -> 3.2709676 | BN24: =((-5*(U22-BN$2))/(BN$1-BN$2))+6 -> 3.2735127 | BO24: =((-5*(V22-BO$2))/(BO$1-BO$2))+6 -> 5.3786982 | BP24: =((5*(W22-BP$2))/(BP$1-BP$2))+1 -> 4.8021262 | BQ24: =((-5*(X22-BQ$2))/(BQ$1-BQ$2))+6 -> 5.7938144 | BR24: =((5*(Y22-BR$2))/(BR$1-BR$2))+1 -> 5.9805574 | BS24: =((5*(Z22-BS$2))/(BS$1-BS$2))+1 -> 5.9964311 | BT24: =((-5*(AA22-BT$2))/(BT$1-BT$2))+6 -> 4.7419838 | BU24: =((-5*(AB22-BU$2))/(BU$1-BU$2))+6 -> 5.0889286 | BV24: =((5*(AC22-BV$2))/(BV$1-BV$2))+1 -> 4.3835878 | BX24: =AVERAGE(BK24:BV24) -> 5.0592173
A25: Austria | B25: =B24+1 -> 2013 | C25: 69.6127 | D25: 21.317783 | E25: 104.98537 | F25: -0.0083690692 | G25: -0.029005634 | H25: 1045.9386 | I25: 12.117104 | J25: 88.438843 | K25: 97.410143 | L25: 0.18720548 | M25: 34.6 | N25: 3.08 | O25: 6485.9844 | P25: 0.21867537 | Q25: 110.23276 | R25: 100 | S25: 99.999998 | T25: 57.538 | U25: 30.8 | V25: 3.2 | W25: 81.136585 | X25: 0.3 | Y25: 99.93 | Z25: 99.980453 | AA25: 0.97297001 | AB25: 11.677 | AC25: 11.788 | AE25: =AVERAGE(BJ27,BX27,BB27) -> 3.5460168 | AG25: 77.309998 | AH25: 0.20424793 | AI25: 21.765268 | AJ25: 35999.222 | AK25: 427.0953 | AL25: 24.592892 | AM25: 62568 | AN25: 94.795705 | AO25: 1.21 | AQ25: 0.71937873 | AR25: 19.07 | AU25: =((-5*(D23-AU$2))/(AU$1-$AU$2))+6 -> 5.0642797 | AV25: =((5*(E23-AV$2))/(AV$1-AV$2))+1 -> 2.1242383 | AW25: =((5*(F23-AW$2))/(AW$1-AW$2))+1 -> 1.841727 | AX25: =((5*(G23-AX$2))/(AX$1-AX$2))+1 -> 1.8146925 | AY25: =((-5*(H23-AY$2))/(AY$1-AY$2))+6 -> 5.011694 | AZ25: =((5*(I23-AZ$2))/(AZ$1-AZ$2))+1 -> 4.0508081 | BA25: =((-5*(J23-BA$2))/(BA$1-BA$2))+6 -> 4.3369146 | BB25: =AVERAGE(AU25:BA25) -> 3.4634792 | BC25: =((-5*(K23-BC$2))/(BC$1-BC$2))+6 -> 1.0774229 | BD25: =((-5*(L23-BD$2))/(BD$1-BD$2))+6 -> 5.4423626 | BE25: =((5*(M23-BE$2))/(BE$1-BE$2))+1 -> 2.8643032 | BF25: =((5*(N23-BF$2))/(BF$1-BF$2))+1 -> 1.7152589 | BG25: =((5*(O23-BG$2))/(BG$1-BG$2))+1 -> 1.0604494 | BH25: =((5*(P23-BH$2))/(BH$1-BH$2))+1 -> 1.0640384 | BI25: =((5*(Q23-BI$2))/(BI$1-BI$2))+1 -> 1.3461553 | BJ25: =AVERAGE(BC25:BI25) -> 2.0814272 | BK25: =((5*(R23-BK$2))/(BK$1-BK$2))+1 -> 6 | BL25: =((5*(S23-BL$2))/(BL$1-BL$2))+1 -> 5.9999997 | BM25: =((5*(T23-BM$2))/(BM$1-BM$2))+1 -> 3.2954478 | BN25: =((-5*(U23-BN$2))/(BN$1-BN$2))+6 -> 3.2280424 | BO25: =((-5*(V23-BO$2))/(BO$1-BO$2))+6 -> 5.408284 | BP25: =((5*(W23-BP$2))/(BP$1-BP$2))+1 -> 4.9232644 | BQ25: =((-5*(X23-BQ$2))/(BQ$1-BQ$2))+6 -> 5.7938144 | BR25: =((5*(Y23-BR$2))/(BR$1-BR$2))+1 -> 5.9773169 | BS25: =((5*(Z23-BS$2))/(BS$1-BS$2))+1 -> 5.995997 | BT25: =((-5*(AA23-BT$2))/(BT$1-BT$2))+6 -> 4.7026979 | BU25: =((-5*(AB23-BU$2))/(BU$1-BU$2))+6 -> 5.1581877 | BV25: =((5*(AC23-BV$2))/(BV$1-BV$2))+1 -> 4.3810433 | BX25: =AVERAGE(BK25:BV25) -> 5.072008
A26: Austria | B26: =B25+1 -> 2014 | C26: 65.929 | D26: 21.246378 | E26: 104.49674 | F26: -0.00028580322 | G26: 0.50538887 | H26: 999.38837 | I26: 12.494228 | J26: 96.679692 | K26: 95.768355 | L26: 0.17596914 | M26: 35.7 | N26: 2.95 | O26: 6435.4913 | P26: 0.19184654 | Q26: 112.36123 | R26: 100 | S26: 100 | T26: 57.16 | U26: 30.5 | V26: 3.1 | W26: 81.490244 | X26: 0.2 | Y26: 99.93 | Z26: 99.978588 | AA26: 0.97232002 | AB26: 11.158 | AC26: 12.014 | AE26: =AVERAGE(BJ28,BX28,BB28) -> 3.5700119 | AG26: 78.43 | AH26: 1.0582602 | AI26: 21.922366 | AJ26: 36036.895 | AK26: 432.6374 | AL26: 27.20212 | AM26: 62801 | AN26: 89.394312 | AO26: 1.21 | AP26: 7.2 | AQ26: 0.49145423 | AR26: 19.07 | AU26: =((-5*(D24-AU$2))/(AU$1-$AU$2))+6 -> 5.0965812 | AV26: =((5*(E24-AV$2))/(AV$1-AV$2))+1 -> 2.125121 | AW26: =((5*(F24-AW$2))/(AW$1-AW$2))+1 -> 1.8282311 | AX26: =((5*(G24-AX$2))/(AX$1-AX$2))+1 -> 1.7356111 | AY26: =((-5*(H24-AY$2))/(AY$1-AY$2))+6 -> 5.0472587 | AZ26: =((5*(I24-AZ$2))/(AZ$1-AZ$2))+1 -> 3.9512305 | BA26: =((-5*(J24-BA$2))/(BA$1-BA$2))+6 -> 4.2357055 | BB26: =AVERAGE(AU26:BA26) -> 3.4313913 | BC26: =((-5*(K24-BC$2))/(BC$1-BC$2))+6 -> 1.0371415 | BD26: =((-5*(L24-BD$2))/(BD$1-BD$2))+6 -> 5.478026 | BE26: =((5*(M24-BE$2))/(BE$1-BE$2))+1 -> 3.0354523 | BF26: =((5*(N24-BF$2))/(BF$1-BF$2))+1 -> 1.7050409 | BG26: =((5*(O24-BG$2))/(BG$1-BG$2))+1 -> 1.060171 | BH26: =((5*(P24-BH$2))/(BH$1-BH$2))+1 -> 1.0624204 | BI26: =((5*(Q24-BI$2))/(BI$1-BI$2))+1 -> 1.3526219 | BJ26: =AVERAGE(BC26:BI26) -> 2.1044106 | BK26: =((5*(R24-BK$2))/(BK$1-BK$2))+1 -> 6 | BL26: =((5*(S24-BL$2))/(BL$1-BL$2))+1 -> 5.9999983 | BM26: =((5*(T24-BM$2))/(BM$1-BM$2))+1 -> 3.3082003 | BN26: =((-5*(U24-BN$2))/(BN$1-BN$2))+6 -> 3.2553246 | BO26: =((-5*(V24-BO$2))/(BO$1-BO$2))+6 -> 5.4674556 | BP26: =((5*(W24-BP$2))/(BP$1-BP$2))+1 -> 4.9093152 | BQ26: =((-5*(X24-BQ$2))/(BQ$1-BQ$2))+6 -> 5.742268 | BR26: =((5*(Y24-BR$2))/(BR$1-BR$2))+1 -> 5.9773169 | BS26: =((5*(Z24-BS$2))/(BS$1-BS$2))+1 -> 5.9955426 | BT26: =((-5*(AA24-BT$2))/(BT$1-BT$2))+6 -> 4.6596568 | BU26: =((-5*(AB24-BU$2))/(BU$1-BU$2))+6 -> 5.213469 | BV26: =((5*(AC24-BV$2))/(BV$1-BV$2))+1 -> 4.4071247 | BX26: =AVERAGE(BK26:BV26) -> 5.0779727
A27: Austria | B27: =B26+1 -> 2015 | C27: 67.3691 | D27: 21.274592 | E27: 103.11758 | F27: 0.0017425951 | G27: 0.32143845 | H27: 983.698 | I27: 12.323364 | J27: 95.691792 | K27: 93.785672 | L27: 0.17749912 | M27: 34.8 | N27: 2.99 | O27: 6363.7528 | P27: 0.13471108 | Q27: 115.16908 | R27: 100 | S27: 99.999999 | T27: 57.115 | U27: 30.5 | V27: 3.1 | W27: 81.190244 | X27: 0.6 | Y27: 99.93 | Z27: 99.976705 | AA27: 0.97283 | AB27: 11.101 | AC27: 12.077 | AE27: =AVERAGE(BJ29,BX29,BB29) -> 3.561068 | AF27: 506 | AG27: 79.010002 | AH27: 0.48914705 | AI27: 22.071707 | AJ27: 35811.686 | AK27: 439.2231 | AL27: 29.215446 | AM27: 63231 | AN27: 92.519776 | AO27: 1.58 | AP27: 7.119 | AQ27: 0.5091166 | AR27: 19.07 | AU27: =((-5*(D25-AU$2))/(AU$1-$AU$2))+6 -> 5.1163841 | AV27: =((5*(E25-AV$2))/(AV$1-AV$2))+1 -> 2.113627 | AW27: =((5*(F25-AW$2))/(AW$1-AW$2))+1 -> 1.8225912 | AX27: =((5*(G25-AX$2))/(AX$1-AX$2))+1 -> 1.6768844 | AY27: =((-5*(H25-AY$2))/(AY$1-AY$2))+6 -> 5.0794782 | AZ27: =((5*(I25-AZ$2))/(AZ$1-AZ$2))+1 -> 3.8851187 | BA27: =((-5*(J25-BA$2))/(BA$1-BA$2))+6 -> 4.2919878 | BB27: =AVERAGE(AU27:BA27) -> 3.4265816 | BC27: =((-5*(K25-BC$2))/(BC$1-BC$2))+6 -> 1.1294928 | BD27: =((-5*(L25-BD$2))/(BD$1-BD$2))+6 -> 5.4705353 | BE27: =((5*(M25-BE$2))/(BE$1-BE$2))+1 -> 3.0476773 | BF27: =((5*(N25-BF$2))/(BF$1-BF$2))+1 -> 1.7186649 | BG27: =((5*(O25-BG$2))/(BG$1-BG$2))+1 -> 1.059813 | BH27: =((5*(P25-BH$2))/(BH$1-BH$2))+1 -> 1.0572299 | BI27: =((5*(Q25-BI$2))/(BI$1-BI$2))+1 -> 1.3559559 | BJ27: =AVERAGE(BC27:BI27) -> 2.1199099 | BK27: =((5*(R25-BK$2))/(BK$1-BK$2))+1 -> 6 | BL27: =((5*(S25-BL$2))/(BL$1-BL$2))+1 -> 5.9999989 | BM27: =((5*(T25-BM$2))/(BM$1-BM$2))+1 -> 3.2931706 | BN27: =((-5*(U25-BN$2))/(BN$1-BN$2))+6 -> 3.2280424 | BO27: =((-5*(V25-BO$2))/(BO$1-BO$2))+6 -> 5.4970414 | BP27: =((5*(W25-BP$2))/(BP$1-BP$2))+1 -> 4.9695172 | BQ27: =((-5*(X25-BQ$2))/(BQ$1-BQ$2))+6 -> 5.8453608 | BR27: =((5*(Y25-BR$2))/(BR$1-BR$2))+1 -> 5.9773169 | BS27: =((5*(Z25-BS$2))/(BS$1-BS$2))+1 -> 5.9950752 | BT27: =((-5*(AA25-BT$2))/(BT$1-BT$2))+6 -> 4.6192156 | BU27: =((-5*(AB25-BU$2))/(BU$1-BU$2))+6 -> 5.243943 | BV27: =((5*(AC25-BV$2))/(BV$1-BV$2))+1 -> 4.4300254 | BX27: =AVERAGE(BK27:BV27) -> 5.091559
A28: Austria | B28: =B27+1 -> 2016 | C28: 67.7825 | D28: 21.399157 | E28: 101.57349 | F28: 0.010188773 | G28: 0.15065962 | H28: 1032.6985 | I28: 13.741241 | J28: 95.21178 | K28: 91.474465 | L28: 0.17488561 | M28: 34.6 | N28: 2.96 | O28: 6295.3062 | P28: 0.11104244 | Q28: 119.01185 | R28: 100 | S28: 100 | T28: 57.427 | U28: 30.8 | V28: 3 | W28: 81.641463 | X28: 0.6 | Y28: 99.93 | Z28: 99.974814 | AA28: 0.97198999 | AB28: 10.969 | AC28: 12.115 | AE28: =AVERAGE(BJ30,BX30,BB30) -> 3.5749172 | AG28: 79.370003 | AH28: 0.23384432 | AI28: 22.123237 | AJ28: 36760.942 | AK28: 438.7894 | AL28: 32.288681 | AM28: 63860 | AN28: 92.63186 | AO28: 1.58 | AP28: 7.006 | AQ28: 0.61809745 | AR28: 19.07 | AU28: =((-5*(D26-AU$2))/(AU$1-$AU$2))+6 -> 5.1272643 | AV28: =((5*(E26-AV$2))/(AV$1-AV$2))+1 -> 2.1070613 | AW28: =((5*(F26-AW$2))/(AW$1-AW$2))+1 -> 1.8271166 | AX28: =((5*(G26-AX$2))/(AX$1-AX$2))+1 -> 1.8742074 | AY28: =((-5*(H26-AY$2))/(AY$1-AY$2))+6 -> 5.1204467 | AZ28: =((5*(I26-AZ$2))/(AZ$1-AZ$2))+1 -> 3.931481 | BA28: =((-5*(J26-BA$2))/(BA$1-BA$2))+6 -> 4.1234573 | BB28: =AVERAGE(AU28:BA28) -> 3.4444335 | BC28: =((-5*(K26-BC$2))/(BC$1-BC$2))+6 -> 1.2115822 | BD28: =((-5*(L26-BD$2))/(BD$1-BD$2))+6 -> 5.5117887 | BE28: =((5*(M26-BE$2))/(BE$1-BE$2))+1 -> 3.1149144 | BF28: =((5*(N26-BF$2))/(BF$1-BF$2))+1 -> 1.6743869 | BG28: =((5*(O26-BG$2))/(BG$1-BG$2))+1 -> 1.0593416 | BH28: =((5*(P26-BH$2))/(BH$1-BH$2))+1 -> 1.0502085 | BI28: =((5*(Q26-BI$2))/(BI$1-BI$2))+1 -> 1.3631794 | BJ28: =AVERAGE(BC28:BI28) -> 2.1407717 | BK28: =((5*(R26-BK$2))/(BK$1-BK$2))+1 -> 6 | BL28: =((5*(S26-BL$2))/(BL$1-BL$2))+1 -> 6 | BM28: =((5*(T26-BM$2))/(BM$1-BM$2))+1 -> 3.2501309 | BN28: =((-5*(U26-BN$2))/(BN$1-BN$2))+6 -> 3.2553246 | BO28: =((-5*(V26-BO$2))/(BO$1-BO$2))+6 -> 5.5266272 | BP28: =((5*(W26-BP$2))/(BP$1-BP$2))+1 -> 5.075972 | BQ28: =((-5*(X26-BQ$2))/(BQ$1-BQ$2))+6 -> 5.8969072 | BR28: =((5*(Y26-BR$2))/(BR$1-BR$2))+1 -> 5.9773169 | BS28: =((5*(Z26-BS$2))/(BS$1-BS$2))+1 -> 5.9946054 | BT28: =((-5*(AA26-BT$2))/(BT$1-BT$2))+6 -> 4.6379917 | BU28: =((-5*(AB26-BU$2))/(BU$1-BU$2))+6 -> 5.3092983 | BV28: =((5*(AC26-BV$2))/(BV$1-BV$2))+1 -> 4.5737913 | BX28: =AVERAGE(BK28:BV28) -> 5.1248305
A29: Austria | B29: =B28+1 -> 2017 | C29: 70.1063 | D29: 21.523678 | E29: 105.55607 | F29: 0.015643071 | G29: 0.40446742 | H29: 921.24989 | I29: 12.833337 | J29: 89.908541 | K29: 85.015935 | L29: 0.17686249 | M29: 34 | N29: 2.95 | O29: 6251.7292 | P29: 0.121957 | Q29: 123.18711 | R29: 100 | S29: 100 | T29: 57.703 | U29: 29.7 | V29: 3 | W29: 81.643902 | X29: 0.3 | Y29: 99.93 | Z29: 99.972911 | AA29: 0.97172999 | AB29: 10.892 | AC29: 12.159 | AE29: =AVERAGE(BJ31,BX31,BB31) -> 3.6088146 | AG29: 79.660004 | AH29: 0.39594388 | AI29: 22.278522 | AJ29: 36608.68 | AK29: 446.8202 | AL29: 33.425434 | AM29: 63856 | AN29: 90.176468 | AO29: 1.58 | AP29: 7.1394 | AQ29: 0.79568095 | AR29: 19.07 | AU29: =((-5*(D27-AU$2))/(AU$1-$AU$2))+6 -> 5.1229652 | AV29: =((5*(E27-AV$2))/(AV$1-AV$2))+1 -> 2.08853 | AW29: =((5*(F27-AW$2))/(AW$1-AW$2))+1 -> 1.8282522 | AX29: =((5*(G27-AX$2))/(AX$1-AX$2))+1 -> 1.8062844 | AY29: =((-5*(H27-AY$2))/(AY$1-AY$2))+6 -> 5.1342557 | AZ29: =((5*(I27-AZ$2))/(AZ$1-AZ$2))+1 -> 3.9104755 | BA29: =((-5*(J27-BA$2))/(BA$1-BA$2))+6 -> 4.1436605 | BB29: =AVERAGE(AU29:BA29) -> 3.4334891 | BC29: =((-5*(K27-BC$2))/(BC$1-BC$2))+6 -> 1.3107164 | BD29: =((-5*(L27-BD$2))/(BD$1-BD$2))+6 -> 5.5061715 | BE29: =((5*(M27-BE$2))/(BE$1-BE$2))+1 -> 3.0599022 | BF29: =((5*(N27-BF$2))/(BF$1-BF$2))+1 -> 1.6880109 | BG29: =((5*(O27-BG$2))/(BG$1-BG$2))+1 -> 1.0586717 | BH29: =((5*(P27-BH$2))/(BH$1-BH$2))+1 -> 1.0352555 | BI29: =((5*(Q27-BI$2))/(BI$1-BI$2))+1 -> 1.3727084 | BJ29: =AVERAGE(BC29:BI29) -> 2.1473481 | BK29: =((5*(R27-BK$2))/(BK$1-BK$2))+1 -> 6 | BL29: =((5*(S27-BL$2))/(BL$1-BL$2))+1 -> 5.9999994 | BM29: =((5*(T27-BM$2))/(BM$1-BM$2))+1 -> 3.2450072 | BN29: =((-5*(U27-BN$2))/(BN$1-BN$2))+6 -> 3.2553246 | BO29: =((-5*(V27-BO$2))/(BO$1-BO$2))+6 -> 5.5266272 | BP29: =((5*(W27-BP$2))/(BP$1-BP$2))+1 -> 4.985669 | BQ29: =((-5*(X27-BQ$2))/(BQ$1-BQ$2))+6 -> 5.6907216 | BR29: =((5*(Y27-BR$2))/(BR$1-BR$2))+1 -> 5.9773169 | BS29: =((5*(Z27-BS$2))/(BS$1-BS$2))+1 -> 5.994131 | BT29: =((-5*(AA27-BT$2))/(BT$1-BT$2))+6 -> 4.6232601 | BU29: =((-5*(AB27-BU$2))/(BU$1-BU$2))+6 -> 5.3164761 | BV29: =((5*(AC27-BV$2))/(BV$1-BV$2))+1 -> 4.6138677 | BX29: =AVERAGE(BK29:BV29) -> 5.1023667
